Workbook
Name Bebida_1: CONFIGURACIÓN!$C$5
Name Bebida_2: CONFIGURACIÓN!$C$6
Name Bebida_3: CONFIGURACIÓN!$C$7
Name Color_1: CONFIGURACIÓN!$D$5
Name Color_2: CONFIGURACIÓN!$D$6
Name Color_3: CONFIGURACIÓN!$D$7
Name Importe_1: CONFIGURACIÓN!$B$10
Name Importe_2: CONFIGURACIÓN!$B$11
Name Importe_3: CONFIGURACIÓN!$B$12
Name Importe_4: CONFIGURACIÓN!$B$13
Name Importe_5: CONFIGURACIÓN!$B$14
Name Precio_vaso: CONFIGURACIÓN!$B$23
Name Texto_pie: CONFIGURACIÓN!$B$20
Name Texto_subtitulo: CONFIGURACIÓN!$B$18
Name Texto_tabla: CONFIGURACIÓN!$B$19
Name Texto_titulo: CONFIGURACIÓN!$B$17
Name Valor_1: CONFIGURACIÓN!$B$5
Name Valor_2: CONFIGURACIÓN!$B$6
Name Valor_3: CONFIGURACIÓN!$B$7

Sheet INSTRUCCIONES
B2: CARTEL DE CAMBIO DE DINERO A FICHAS — CÓMO USAR ESTE EXCEL
B4: PASOS
B5: 1. CONFIGURACIÓN: cambia (si hace falta) el valor de las fichas, las bebidas, los colores, los importes y los textos.
B6: 2. CAMBIOS: escribe el nº de fichas de cada combinación en las celdas AMARILLAS (texto azul). Nada más.
B7: 3. Excel calcula solo: valor aportado por cada tipo, total entregado, devolución y ESTADO.
B8: 4. Corrige todo lo que salga en ROJO (REVISAR). La columna 'Observaciones' explica el motivo.
B9: 5. Guarda el Excel (Ctrl+G / Ctrl+S) y ejecuta: python generador_cartel_fichas.py
B10: 6. Se genera cartel_cambio_fichas.png con EXACTAMENTE los números de este Excel.
B12: COLORES DE LAS CELDAS
B13: Amarillo + texto azul → editable (lo escribes tú).
B14: Gris claro → fórmula (no se toca; las hojas están protegidas sin contraseña: Revisar › Desproteger hoja).
B15: Gris oscuro con '—' → ese tipo de ficha no forma parte de la combinación.
... B30: CONFIGURACIÓN (editable) · CAMBIOS (editable: nº de fichas) · DATOS_PYTHON (lo que lee Python; no editar) · CALC_SUGERENCIA (oculta, cálculo de la sugerencia).

Sheet CONFIGURACIÓN
A1: CONFIGURACIÓN DEL CARTEL
A2: Celdas amarillas = editables. El resto se usa en las demás hojas.
A4: Ficha | B4: Valor (€) | C4: Nombre bebida | D4: Color (hex) | E4: ← El color de relleno de la columna D es orientativo; el que usa el cartel es el código hex escrito.
A5: Ficha 1 | B5: 3 | C5: Cerveza | D5: #F4511E
A6: Ficha 2 | B6: 5 | C6: Calimocho | D6: #29A9F0
A7: Ficha 3 | B7: 7 | C7: Cubata | D7: #F5A400
A9: Importe | B9: Cambio (€)
A10: Importe 1 | B10: 10 | C10: ← Si cambias un importe, revisa sus 6 filas en CAMBIOS (saldrán en REVISAR si no cuadran).
A11: Importe 2 | B11: 20
A12: Importe 3 | B12: 50
A13: Importe 4 | B13: 100
A14: Importe 5 | B14: 200
A16: Texto | B16: Contenido
A17: Título | B17: CAMBIO DE DINERO A FICHAS
A18: Subtítulo | B18: TÚ ELIGES • DISFRUTA DEL FESTIVAL
A19: Título tabla | B19: POSIBLES COMBINACIONES DE CAMBIO DE FICHAS
A20: Pie | B20: ¡ELIGE TU COMBINACIÓN, CAMBIA TUS EUROS POR FICHAS Y DISFRUTA!
A22: Extra | B22: Precio (€)
A23: Vaso | B23: 1 | C23: ← Precio de cada vaso. La web lo suma al total.

Sheet CAMBIOS
A1: CAMBIOS — Nº DE FICHAS POR COMBINACIÓN | H1: ="Casillas en REVISAR: "&COUNTIF(L5:L34,"REVISAR") -> Casillas en REVISAR: 0
A2: Escribe solo en las celdas AMARILLAS. Todo lo demás son fórmulas. | H2: ="Casillas NO ES POSIBLE: "&COUNTIF(L5:L34,"NO ES POSIBLE") -> Casillas NO ES POSIBLE: 1
A4: Cambio (€) | B4: Combinación | C4: ="Nº fichas "&Valor_1&" €" -> Nº fichas 3 € | D4: ="Valor "&Valor_1&" € (€)" -> Valor 3 € (€) | E4: ="Nº fichas "&Valor_2&" €" -> Nº fichas 5 € | F4: ="Valor "&Valor_2&" € (€)" -> Valor 5 € (€) | G4: ="Nº fichas "&Valor_3&" €" -> Nº fichas 7 € | H4: ="Valor "&Valor_3&" € (€)" -> Valor 7 € (€) | I4: Nº total de fichas | J4: Total entregado en fichas (€) | K4: Devolución (€) | L4: Estado | M4: Observaciones | N4: Sugerencia (óptima) | P4: AUX: usa ficha 1 | Q4: AUX: usa ficha 2 | R4: AUX: usa ficha 3 | S4: AUX: mínimo necesario (€) | T4: AUX: ficha más alta (€) | U4: AUX: ficha más baja (€)
A5: =Importe_1 -> 10 | B5: ="Solo "&Valor_1&" € ("&Bebida_1&")" -> Solo 3 € (Cerveza) | C5: 3 | D5: =IF($S5>$A5,"—",C5*Valor_1) -> 9 | E5: — | F5: — | G5: — | H5: — | I5: =IF($S5>$A5,"—",SUM(C5,E5,G5)) -> 3 | J5: =IF($S5>$A5,"—",SUM(D5,F5,H5)) -> 9 | K5: =IF($S5>$A5,"—",A5-J5) -> 1 | L5: =IF($S5>$A5,"NO ES POSIBLE",IF(OR(M5="",LEFT(M5,5)="Aviso"),"OK","REVISAR")) -> OK | M5: =IF($S5>$A5,"No cabe ni 1 ficha de cada tipo en "&A5&" €",IF(OR(IF(P5=1,OR(N(C5)<1,N(C5)<>INT(N(C5))),FALSE),IF(Q5=1,OR(N(E5)<1,N(E5)<>INT(N(E5))),FALSE),IF(R5=1,OR(N(G5)<1,N(G5)<>INT(N(G5))),FALSE)),"Falta el nº de fichas (entero, mínimo 1 de cada tipo)",IF(J5>A5,"Las fichas ("&J5&" €) superan el importe",IF(K5>T5,"Devolución mayor que "&T5&" € (ficha más alta): añade fichas",IF(K5>=U5,"Aviso: aún cabría 1 ficha más de "&U5&" €",""))))) | N5: =IF($S5>$A5,"NO ES POSIBLE",IF(CALC_SUGERENCIA!$D5=1,CALC_SUGERENCIA!$F5&" × "&CALC_SUGERENCIA!$B5&" €",CALC_SUGERENCIA!$F5&" × "&CALC_SUGERENCIA!$B5&" € + "&CALC_SUGERENCIA!$G5&" × "&CALC_SUGERENCIA!$C5&" €")&" → devuelve "&CALC_SUGERENCIA!$H5&" €") -> 3 × 3 € → devuelve 1 € | P5: 1 | Q5: 0 | R5: 0 | S5: =P5*Valor_1+Q5*Valor_2+R5*Valor_3 -> 3 | T5: =MAX(P5*Valor_1,Q5*Valor_2,R5*Valor_3) -> 3 | U5: =MIN(IF(P5=1,Valor_1,9E+99),IF(Q5=1,Valor_2,9E+99),IF(R5=1,Valor_3,9E+99)) -> 3
A6: =Importe_1 -> 10 | B6: ="Solo "&Valor_2&" € ("&Bebida_2&")" -> Solo 5 € (Calimocho) | C6: — | D6: — | E6: 2 | F6: =IF($S6>$A6,"—",E6*Valor_2) -> 10 | G6: — | H6: — | I6: =IF($S6>$A6,"—",SUM(C6,E6,G6)) -> 2 | J6: =IF($S6>$A6,"—",SUM(D6,F6,H6)) -> 10 | K6: =IF($S6>$A6,"—",A6-J6) -> 0 | L6: =IF($S6>$A6,"NO ES POSIBLE",IF(OR(M6="",LEFT(M6,5)="Aviso"),"OK","REVISAR")) -> OK | M6: =IF($S6>$A6,"No cabe ni 1 ficha de cada tipo en "&A6&" €",IF(OR(IF(P6=1,OR(N(C6)<1,N(C6)<>INT(N(C6))),FALSE),IF(Q6=1,OR(N(E6)<1,N(E6)<>INT(N(E6))),FALSE),IF(R6=1,OR(N(G6)<1,N(G6)<>INT(N(G6))),FALSE)),"Falta el nº de fichas (entero, mínimo 1 de cada tipo)",IF(J6>A6,"Las fichas ("&J6&" €) superan el importe",IF(K6>T6,"Devolución mayor que "&T6&" € (ficha más alta): añade fichas",IF(K6>=U6,"Aviso: aún cabría 1 ficha más de "&U6&" €",""))))) | N6: =IF($S6>$A6,"NO ES POSIBLE",IF(CALC_SUGERENCIA!$D6=1,CALC_SUGERENCIA!$F6&" × "&CALC_SUGERENCIA!$B6&" €",CALC_SUGERENCIA!$F6&" × "&CALC_SUGERENCIA!$B6&" € + "&CALC_SUGERENCIA!$G6&" × "&CALC_SUGERENCIA!$C6&" €")&" → devuelve "&CALC_SUGERENCIA!$H6&" €") -> 2 × 5 € → devuelve 0 € | P6: 0 | Q6: 1 | R6: 0 | S6: =P6*Valor_1+Q6*Valor_2+R6*Valor_3 -> 5 | T6: =MAX(P6*Valor_1,Q6*Valor_2,R6*Valor_3) -> 5 | U6: =MIN(IF(P6=1,Valor_1,9E+99),IF(Q6=1,Valor_2,9E+99),IF(R6=1,Valor_3,9E+99)) -> 5
A7: =Importe_1 -> 10 | B7: ="Solo "&Valor_3&" € ("&Bebida_3&")" -> Solo 7 € (Cubata) | C7: — | D7: — | E7: — | F7: — | G7: 1 | H7: =IF($S7>$A7,"—",G7*Valor_3) -> 7 | I7: =IF($S7>$A7,"—",SUM(C7,E7,G7)) -> 1 | J7: =IF($S7>$A7,"—",SUM(D7,F7,H7)) -> 7 | K7: =IF($S7>$A7,"—",A7-J7) -> 3 | L7: =IF($S7>$A7,"NO ES POSIBLE",IF(OR(M7="",LEFT(M7,5)="Aviso"),"OK","REVISAR")) -> OK | M7: =IF($S7>$A7,"No cabe ni 1 ficha de cada tipo en "&A7&" €",IF(OR(IF(P7=1,OR(N(C7)<1,N(C7)<>INT(N(C7))),FALSE),IF(Q7=1,OR(N(E7)<1,N(E7)<>INT(N(E7))),FALSE),IF(R7=1,OR(N(G7)<1,N(G7)<>INT(N(G7))),FALSE)),"Falta el nº de fichas (entero, mínimo 1 de cada tipo)",IF(J7>A7,"Las fichas ("&J7&" €) superan el importe",IF(K7>T7,"Devolución mayor que "&T7&" € (ficha más alta): añade fichas",IF(K7>=U7,"Aviso: aún cabría 1 ficha más de "&U7&" €",""))))) | N7: =IF($S7>$A7,"NO ES POSIBLE",IF(CALC_SUGERENCIA!$D7=1,CALC_SUGERENCIA!$F7&" × "&CALC_SUGERENCIA!$B7&" €",CALC_SUGERENCIA!$F7&" × "&CALC_SUGERENCIA!$B7&" € + "&CALC_SUGERENCIA!$G7&" × "&CALC_SUGERENCIA!$C7&" €")&" → devuelve "&CALC_SUGERENCIA!$H7&" €") -> 1 × 7 € → devuelve 3 € | P7: 0 | Q7: 0 | R7: 1 | S7: =P7*Valor_1+Q7*Valor_2+R7*Valor_3 -> 7 | T7: =MAX(P7*Valor_1,Q7*Valor_2,R7*Valor_3) -> 7 | U7: =MIN(IF(P7=1,Valor_1,9E+99),IF(Q7=1,Valor_2,9E+99),IF(R7=1,Valor_3,9E+99)) -> 7
A8: =Importe_1 -> 10 | B8: =Valor_1&" € + "&Valor_2&" € ("&Bebida_1&" + "&Bebida_2&")" -> 3 € + 5 € (Cerveza + Calimocho) | C8: 1 | D8: =IF($S8>$A8,"—",C8*Valor_1) -> 3 | E8: 1 | F8: =IF($S8>$A8,"—",E8*Valor_2) -> 5 | G8: — | H8: — | I8: =IF($S8>$A8,"—",SUM(C8,E8,G8)) -> 2 | J8: =IF($S8>$A8,"—",SUM(D8,F8,H8)) -> 8 | K8: =IF($S8>$A8,"—",A8-J8) -> 2 | L8: =IF($S8>$A8,"NO ES POSIBLE",IF(OR(M8="",LEFT(M8,5)="Aviso"),"OK","REVISAR")) -> OK | M8: =IF($S8>$A8,"No cabe ni 1 ficha de cada tipo en "&A8&" €",IF(OR(IF(P8=1,OR(N(C8)<1,N(C8)<>INT(N(C8))),FALSE),IF(Q8=1,OR(N(E8)<1,N(E8)<>INT(N(E8))),FALSE),IF(R8=1,OR(N(G8)<1,N(G8)<>INT(N(G8))),FALSE)),"Falta el nº de fichas (entero, mínimo 1 de cada tipo)",IF(J8>A8,"Las fichas ("&J8&" €) superan el importe",IF(K8>T8,"Devolución mayor que "&T8&" € (ficha más alta): añade fichas",IF(K8>=U8,"Aviso: aún cabría 1 ficha más de "&U8&" €",""))))) | N8: =IF($S8>$A8,"NO ES POSIBLE",IF(CALC_SUGERENCIA!$D8=1,CALC_SUGERENCIA!$F8&" × "&CALC_SUGERENCIA!$B8&" €",CALC_SUGERENCIA!$F8&" × "&CALC_SUGERENCIA!$B8&" € + "&CALC_SUGERENCIA!$G8&" × "&CALC_SUGERENCIA!$C8&" €")&" → devuelve "&CALC_SUGERENCIA!$H8&" €") -> 1 × 3 € + 1 × 5 € → devuelve 2 € | P8: 1 | Q8: 1 | R8: 0 | S8: =P8*Valor_1+Q8*Valor_2+R8*Valor_3 -> 8 | T8: =MAX(P8*Valor_1,Q8*Valor_2,R8*Valor_3) -> 5 | U8: =MIN(IF(P8=1,Valor_1,9E+99),IF(Q8=1,Valor_2,9E+99),IF(R8=1,Valor_3,9E+99)) -> 3
A9: =Importe_1 -> 10 | B9: =Valor_1&" € + "&Valor_3&" € ("&Bebida_1&" + "&Bebida_3&")" -> 3 € + 7 € (Cerveza + Cubata) | C9: 1 | D9: =IF($S9>$A9,"—",C9*Valor_1) -> 3 | E9: — | F9: — | G9: 1 | H9: =IF($S9>$A9,"—",G9*Valor_3) -> 7 | I9: =IF($S9>$A9,"—",SUM(C9,E9,G9)) -> 2 | J9: =IF($S9>$A9,"—",SUM(D9,F9,H9)) -> 10 | K9: =IF($S9>$A9,"—",A9-J9) -> 0 | L9: =IF($S9>$A9,"NO ES POSIBLE",IF(OR(M9="",LEFT(M9,5)="Aviso"),"OK","REVISAR")) -> OK | M9: =IF($S9>$A9,"No cabe ni 1 ficha de cada tipo en "&A9&" €",IF(OR(IF(P9=1,OR(N(C9)<1,N(C9)<>INT(N(C9))),FALSE),IF(Q9=1,OR(N(E9)<1,N(E9)<>INT(N(E9))),FALSE),IF(R9=1,OR(N(G9)<1,N(G9)<>INT(N(G9))),FALSE)),"Falta el nº de fichas (entero, mínimo 1 de cada tipo)",IF(J9>A9,"Las fichas ("&J9&" €) superan el importe",IF(K9>T9,"Devolución mayor que "&T9&" € (ficha más alta): añade fichas",IF(K9>=U9,"Aviso: aún cabría 1 ficha más de "&U9&" €",""))))) | N9: =IF($S9>$A9,"NO ES POSIBLE",IF(CALC_SUGERENCIA!$D9=1,CALC_SUGERENCIA!$F9&" × "&CALC_SUGERENCIA!$B9&" €",CALC_SUGERENCIA!$F9&" × "&CALC_SUGERENCIA!$B9&" € + "&CALC_SUGERENCIA!$G9&" × "&CALC_SUGERENCIA!$C9&" €")&" → devuelve "&CALC_SUGERENCIA!$H9&" €") -> 1 × 3 € + 1 × 7 € → devuelve 0 € | P9: 1 | Q9: 0 | R9: 1 | S9: =P9*Valor_1+Q9*Valor_2+R9*Valor_3 -> 10 | T9: =MAX(P9*Valor_1,Q9*Valor_2,R9*Valor_3) -> 7 | U9: =MIN(IF(P9=1,Valor_1,9E+99),IF(Q9=1,Valor_2,9E+99),IF(R9=1,Valor_3,9E+99)) -> 3
A10: =Importe_1 -> 10 | B10: =Valor_2&" € + "&Valor_3&" € ("&Bebida_2&" + "&Bebida_3&")" -> 5 € + 7 € (Calimocho + Cubata) | C10: — | D10: — | F10: =IF($S10>$A10,"—",E10*Valor_2) -> — | H10: =IF($S10>$A10,"—",G10*Valor_3) -> — | I10: =IF($S10>$A10,"—",SUM(C10,E10,G10)) -> — | J10: =IF($S10>$A10,"—",SUM(D10,F10,H10)) -> — | K10: =IF($S10>$A10,"—",A10-J10) -> — | L10: =IF($S10>$A10,"NO ES POSIBLE",IF(OR(M10="",LEFT(M10,5)="Aviso"),"OK","REVISAR")) -> NO ES POSIBLE | M10: =IF($S10>$A10,"No cabe ni 1 ficha de cada tipo en "&A10&" €",IF(OR(IF(P10=1,OR(N(C10)<1,N(C10)<>INT(N(C10))),FALSE),IF(Q10=1,OR(N(E10)<1,N(E10)<>INT(N(E10))),FALSE),IF(R10=1,OR(N(G10)<1,N(G10)<>INT(N(G10))),FALSE)),"Falta el nº de fichas (entero, mínimo 1 de cada tipo)",IF(J10>A10,"Las fichas ("&J10&" €) superan el importe",IF(K10>T10,"Devolución mayor que "&T10&" € (ficha más alta): añade fichas",IF(K10>=U10,"Aviso: aún cabría 1 ficha más de "&U10&" €",""))))) -> No cabe ni 1 ficha de cada tipo en 10 € | N10: =IF($S10>$A10,"NO ES POSIBLE",IF(CALC_SUGERENCIA!$D10=1,CALC_SUGERENCIA!$F10&" × "&CALC_SUGERENCIA!$B10&" €",CALC_SUGERENCIA!$F10&" × "&CALC_SUGERENCIA!$B10&" € + "&CALC_SUGERENCIA!$G10&" × "&CALC_SUGERENCIA!$C10&" €")&" → devuelve "&CALC_SUGERENCIA!$H10&" €") -> NO ES POSIBLE | P10: 0 | Q10: 1 | R10: 1 | S10: =P10*Valor_1+Q10*Valor_2+R10*Valor_3 -> 12 | T10: =MAX(P10*Valor_1,Q10*Valor_2,R10*Valor_3) -> 7 | U10: =MIN(IF(P10=1,Valor_1,9E+99),IF(Q10=1,Valor_2,9E+99),IF(R10=1,Valor_3,9E+99)) -> 5
A11: =Importe_2 -> 20 | B11: ="Solo "&Valor_1&" € ("&Bebida_1&")" -> Solo 3 € (Cerveza) | C11: 6 | D11: =IF($S11>$A11,"—",C11*Valor_1) -> 18 | E11: — | F11: — | G11: — | H11: — | I11: =IF($S11>$A11,"—",SUM(C11,E11,G11)) -> 6 | J11: =IF($S11>$A11,"—",SUM(D11,F11,H11)) -> 18 | K11: =IF($S11>$A11,"—",A11-J11) -> 2 | L11: =IF($S11>$A11,"NO ES POSIBLE",IF(OR(M11="",LEFT(M11,5)="Aviso"),"OK","REVISAR")) -> OK | M11: =IF($S11>$A11,"No cabe ni 1 ficha de cada tipo en "&A11&" €",IF(OR(IF(P11=1,OR(N(C11)<1,N(C11)<>INT(N(C11))),FALSE),IF(Q11=1,OR(N(E11)<1,N(E11)<>INT(N(E11))),FALSE),IF(R11=1,OR(N(G11)<1,N(G11)<>INT(N(G11))),FALSE)),"Falta el nº de fichas (entero, mínimo 1 de cada tipo)",IF(J11>A11,"Las fichas ("&J11&" €) superan el importe",IF(K11>T11,"Devolución mayor que "&T11&" € (ficha más alta): añade fichas",IF(K11>=U11,"Aviso: aún cabría 1 ficha más de "&U11&" €",""))))) | N11: =IF($S11>$A11,"NO ES POSIBLE",IF(CALC_SUGERENCIA!$D11=1,CALC_SUGERENCIA!$F11&" × "&CALC_SUGERENCIA!$B11&" €",CALC_SUGERENCIA!$F11&" × "&CALC_SUGERENCIA!$B11&" € + "&CALC_SUGERENCIA!$G11&" × "&CALC_SUGERENCIA!$C11&" €")&" → devuelve "&CALC_SUGERENCIA!$H11&" €") -> 6 × 3 € → devuelve 2 € | P11: 1 | Q11: 0 | R11: 0 | S11: =P11*Valor_1+Q11*Valor_2+R11*Valor_3 -> 3 | T11: =MAX(P11*Valor_1,Q11*Valor_2,R11*Valor_3) -> 3 | U11: =MIN(IF(P11=1,Valor_1,9E+99),IF(Q11=1,Valor_2,9E+99),IF(R11=1,Valor_3,9E+99)) -> 3
A12: =Importe_2 -> 20 | B12: ="Solo "&Valor_2&" € ("&Bebida_2&")" -> Solo 5 € (Calimocho) | C12: — | D12: — | E12: 4 | F12: =IF($S12>$A12,"—",E12*Valor_2) -> 20 | G12: — | H12: — | I12: =IF($S12>$A12,"—",SUM(C12,E12,G12)) -> 4 | J12: =IF($S12>$A12,"—",SUM(D12,F12,H12)) -> 20 | K12: =IF($S12>$A12,"—",A12-J12) -> 0 | L12: =IF($S12>$A12,"NO ES POSIBLE",IF(OR(M12="",LEFT(M12,5)="Aviso"),"OK","REVISAR")) -> OK | M12: =IF($S12>$A12,"No cabe ni 1 ficha de cada tipo en "&A12&" €",IF(OR(IF(P12=1,OR(N(C12)<1,N(C12)<>INT(N(C12))),FALSE),IF(Q12=1,OR(N(E12)<1,N(E12)<>INT(N(E12))),FALSE),IF(R12=1,OR(N(G12)<1,N(G12)<>INT(N(G12))),FALSE)),"Falta el nº de fichas (entero, mínimo 1 de cada tipo)",IF(J12>A12,"Las fichas ("&J12&" €) superan el importe",IF(K12>T12,"Devolución mayor que "&T12&" € (ficha más alta): añade fichas",IF(K12>=U12,"Aviso: aún cabría 1 ficha más de "&U12&" €",""))))) | N12: =IF($S12>$A12,"NO ES POSIBLE",IF(CALC_SUGERENCIA!$D12=1,CALC_SUGERENCIA!$F12&" × "&CALC_SUGERENCIA!$B12&" €",CALC_SUGERENCIA!$F12&" × "&CALC_SUGERENCIA!$B12&" € + "&CALC_SUGERENCIA!$G12&" × "&CALC_SUGERENCIA!$C12&" €")&" → devuelve "&CALC_SUGERENCIA!$H12&" €") -> 4 × 5 € → devuelve 0 € | P12: 0 | Q12: 1 | R12: 0 | S12: =P12*Valor_1+Q12*Valor_2+R12*Valor_3 -> 5 | T12: =MAX(P12*Valor_1,Q12*Valor_2,R12*Valor_3) -> 5 | U12: =MIN(IF(P12=1,Valor_1,9E+99),IF(Q12=1,Valor_2,9E+99),IF(R12=1,Valor_3,9E+99)) -> 5
A13: =Importe_2 -> 20 | B13: ="Solo "&Valor_3&" € ("&Bebida_3&")" -> Solo 7 € (Cubata) | C13: — | D13: — | E13: — | F13: — | G13: 2 | H13: =IF($S13>$A13,"—",G13*Valor_3) -> 14 | I13: =IF($S13>$A13,"—",SUM(C13,E13,G13)) -> 2 | J13: =IF($S13>$A13,"—",SUM(D13,F13,H13)) -> 14 | K13: =IF($S13>$A13,"—",A13-J13) -> 6 | L13: =IF($S13>$A13,"NO ES POSIBLE",IF(OR(M13="",LEFT(M13,5)="Aviso"),"OK","REVISAR")) -> OK | M13: =IF($S13>$A13,"No cabe ni 1 ficha de cada tipo en "&A13&" €",IF(OR(IF(P13=1,OR(N(C13)<1,N(C13)<>INT(N(C13))),FALSE),IF(Q13=1,OR(N(E13)<1,N(E13)<>INT(N(E13))),FALSE),IF(R13=1,OR(N(G13)<1,N(G13)<>INT(N(G13))),FALSE)),"Falta el nº de fichas (entero, mínimo 1 de cada tipo)",IF(J13>A13,"Las fichas ("&J13&" €) superan el importe",IF(K13>T13,"Devolución mayor que "&T13&" € (ficha más alta): añade fichas",IF(K13>=U13,"Aviso: aún cabría 1 ficha más de "&U13&" €",""))))) | N13: =IF($S13>$A13,"NO ES POSIBLE",IF(CALC_SUGERENCIA!$D13=1,CALC_SUGERENCIA!$F13&" × "&CALC_SUGERENCIA!$B13&" €",CALC_SUGERENCIA!$F13&" × "&CALC_SUGERENCIA!$B13&" € + "&CALC_SUGERENCIA!$G13&" × "&CALC_SUGERENCIA!$C13&" €")&" → devuelve "&CALC_SUGERENCIA!$H13&" €") -> 2 × 7 € → devuelve 6 € | P13: 0 | Q13: 0 | R13: 1 | S13: =P13*Valor_1+Q13*Valor_2+R13*Valor_3 -> 7 | T13: =MAX(P13*Valor_1,Q13*Valor_2,R13*Valor_3) -> 7 | U13: =MIN(IF(P13=1,Valor_1,9E+99),IF(Q13=1,Valor_2,9E+99),IF(R13=1,Valor_3,9E+99)) -> 7
A14: =Importe_2 -> 20 | B14: =Valor_1&" € + "&Valor_2&" € ("&Bebida_1&" + "&Bebida_2&")" -> 3 € + 5 € (Cerveza + Calimocho) | C14: 3 | D14: =IF($S14>$A14,"—",C14*Valor_1) -> 9 | E14: 2 | F14: =IF($S14>$A14,"—",E14*Valor_2) -> 10 | G14: — | H14: — | I14: =IF($S14>$A14,"—",SUM(C14,E14,G14)) -> 5 | J14: =IF($S14>$A14,"—",SUM(D14,F14,H14)) -> 19 | K14: =IF($S14>$A14,"—",A14-J14) -> 1 | L14: =IF($S14>$A14,"NO ES POSIBLE",IF(OR(M14="",LEFT(M14,5)="Aviso"),"OK","REVISAR")) -> OK | M14: =IF($S14>$A14,"No cabe ni 1 ficha de cada tipo en "&A14&" €",IF(OR(IF(P14=1,OR(N(C14)<1,N(C14)<>INT(N(C14))),FALSE),IF(Q14=1,OR(N(E14)<1,N(E14)<>INT(N(E14))),FALSE),IF(R14=1,OR(N(G14)<1,N(G14)<>INT(N(G14))),FALSE)),"Falta el nº de fichas (entero, mínimo 1 de cada tipo)",IF(J14>A14,"Las fichas ("&J14&" €) superan el importe",IF(K14>T14,"Devolución mayor que "&T14&" € (ficha más alta): añade fichas",IF(K14>=U14,"Aviso: aún cabría 1 ficha más de "&U14&" €",""))))) | N14: =IF($S14>$A14,"NO ES POSIBLE",IF(CALC_SUGERENCIA!$D14=1,CALC_SUGERENCIA!$F14&" × "&CALC_SUGERENCIA!$B14&" €",CALC_SUGERENCIA!$F14&" × "&CALC_SUGERENCIA!$B14&" € + "&CALC_SUGERENCIA!$G14&" × "&CALC_SUGERENCIA!$C14&" €")&" → devuelve "&CALC_SUGERENCIA!$H14&" €") -> 5 × 3 € + 1 × 5 € → devuelve 0 € | P14: 1 | Q14: 1 | R14: 0 | S14: =P14*Valor_1+Q14*Valor_2+R14*Valor_3 -> 8 | T14: =MAX(P14*Valor_1,Q14*Valor_2,R14*Valor_3) -> 5 | U14: =MIN(IF(P14=1,Valor_1,9E+99),IF(Q14=1,Valor_2,9E+99),IF(R14=1,Valor_3,9E+99)) -> 3
A15: =Importe_2 -> 20 | B15: =Valor_1&" € + "&Valor_3&" € ("&Bebida_1&" + "&Bebida_3&")" -> 3 € + 7 € (Cerveza + Cubata) | C15: 2 | D15: =IF($S15>$A15,"—",C15*Valor_1) -> 6 | E15: — | F15: — | G15: 2 | H15: =IF($S15>$A15,"—",G15*Valor_3) -> 14 | I15: =IF($S15>$A15,"—",SUM(C15,E15,G15)) -> 4 | J15: =IF($S15>$A15,"—",SUM(D15,F15,H15)) -> 20 | K15: =IF($S15>$A15,"—",A15-J15) -> 0 | L15: =IF($S15>$A15,"NO ES POSIBLE",IF(OR(M15="",LEFT(M15,5)="Aviso"),"OK","REVISAR")) -> OK | M15: =IF($S15>$A15,"No cabe ni 1 ficha de cada tipo en "&A15&" €",IF(OR(IF(P15=1,OR(N(C15)<1,N(C15)<>INT(N(C15))),FALSE),IF(Q15=1,OR(N(E15)<1,N(E15)<>INT(N(E15))),FALSE),IF(R15=1,OR(N(G15)<1,N(G15)<>INT(N(G15))),FALSE)),"Falta el nº de fichas (entero, mínimo 1 de cada tipo)",IF(J15>A15,"Las fichas ("&J15&" €) superan el importe",IF(K15>T15,"Devolución mayor que "&T15&" € (ficha más alta): añade fichas",IF(K15>=U15,"Aviso: aún cabría 1 ficha más de "&U15&" €",""))))) | N15: =IF($S15>$A15,"NO ES POSIBLE",IF(CALC_SUGERENCIA!$D15=1,CALC_SUGERENCIA!$F15&" × "&CALC_SUGERENCIA!$B15&" €",CALC_SUGERENCIA!$F15&" × "&CALC_SUGERENCIA!$B15&" € + "&CALC_SUGERENCIA!$G15&" × "&CALC_SUGERENCIA!$C15&" €")&" → devuelve "&CALC_SUGERENCIA!$H15&" €") -> 2 × 3 € + 2 × 7 € → devuelve 0 € | P15: 1 | Q15: 0 | R15: 1 | S15: =P15*Valor_1+Q15*Valor_2+R15*Valor_3 -> 10 | T15: =MAX(P15*Valor_1,Q15*Valor_2,R15*Valor_3) -> 7 | U15: =MIN(IF(P15=1,Valor_1,9E+99),IF(Q15=1,Valor_2,9E+99),IF(R15=1,Valor_3,9E+99)) -> 3
A16: =Importe_2 -> 20 | B16: =Valor_2&" € + "&Valor_3&" € ("&Bebida_2&" + "&Bebida_3&")" -> 5 € + 7 € (Calimocho + Cubata) | C16: — | D16: — | E16: 1 | F16: =IF($S16>$A16,"—",E16*Valor_2) -> 5 | G16: 2 | H16: =IF($S16>$A16,"—",G16*Valor_3) -> 14 | I16: =IF($S16>$A16,"—",SUM(C16,E16,G16)) -> 3 | J16: =IF($S16>$A16,"—",SUM(D16,F16,H16)) -> 19 | K16: =IF($S16>$A16,"—",A16-J16) -> 1 | L16: =IF($S16>$A16,"NO ES POSIBLE",IF(OR(M16="",LEFT(M16,5)="Aviso"),"OK","REVISAR")) -> OK | M16: =IF($S16>$A16,"No cabe ni 1 ficha de cada tipo en "&A16&" €",IF(OR(IF(P16=1,OR(N(C16)<1,N(C16)<>INT(N(C16))),FALSE),IF(Q16=1,OR(N(E16)<1,N(E16)<>INT(N(E16))),FALSE),IF(R16=1,OR(N(G16)<1,N(G16)<>INT(N(G16))),FALSE)),"Falta el nº de fichas (entero, mínimo 1 de cada tipo)",IF(J16>A16,"Las fichas ("&J16&" €) superan el importe",IF(K16>T16,"Devolución mayor que "&T16&" € (ficha más alta): añade fichas",IF(K16>=U16,"Aviso: aún cabría 1 ficha más de "&U16&" €",""))))) | N16: =IF($S16>$A16,"NO ES POSIBLE",IF(CALC_SUGERENCIA!$D16=1,CALC_SUGERENCIA!$F16&" × "&CALC_SUGERENCIA!$B16&" €",CALC_SUGERENCIA!$F16&" × "&CALC_SUGERENCIA!$B16&" € + "&CALC_SUGERENCIA!$G16&" × "&CALC_SUGERENCIA!$C16&" €")&" → devuelve "&CALC_SUGERENCIA!$H16&" €") -> 1 × 5 € + 2 × 7 € → devuelve 1 € | P16: 0 | Q16: 1 | R16: 1 | S16: =P16*Valor_1+Q16*Valor_2+R16*Valor_3 -> 12 | T16: =MAX(P16*Valor_1,Q16*Valor_2,R16*Valor_3) -> 7 | U16: =MIN(IF(P16=1,Valor_1,9E+99),IF(Q16=1,Valor_2,9E+99),IF(R16=1,Valor_3,9E+99)) -> 5
A17: =Importe_3 -> 50 | B17: ="Solo "&Valor_1&" € ("&Bebida_1&")" -> Solo 3 € (Cerveza) | C17: 16 | D17: =IF($S17>$A17,"—",C17*Valor_1) -> 48 | E17: — | F17: — | G17: — | H17: — | I17: =IF($S17>$A17,"—",SUM(C17,E17,G17)) -> 16 | J17: =IF($S17>$A17,"—",SUM(D17,F17,H17)) -> 48 | K17: =IF($S17>$A17,"—",A17-J17) -> 2 | L17: =IF($S17>$A17,"NO ES POSIBLE",IF(OR(M17="",LEFT(M17,5)="Aviso"),"OK","REVISAR")) -> OK | M17: =IF($S17>$A17,"No cabe ni 1 ficha de cada tipo en "&A17&" €",IF(OR(IF(P17=1,OR(N(C17)<1,N(C17)<>INT(N(C17))),FALSE),IF(Q17=1,OR(N(E17)<1,N(E17)<>INT(N(E17))),FALSE),IF(R17=1,OR(N(G17)<1,N(G17)<>INT(N(G17))),FALSE)),"Falta el nº de fichas (entero, mínimo 1 de cada tipo)",IF(J17>A17,"Las fichas ("&J17&" €) superan el importe",IF(K17>T17,"Devolución mayor que "&T17&" € (ficha más alta): añade fichas",IF(K17>=U17,"Aviso: aún cabría 1 ficha más de "&U17&" €",""))))) | N17: =IF($S17>$A17,"NO ES POSIBLE",IF(CALC_SUGERENCIA!$D17=1,CALC_SUGERENCIA!$F17&" × "&CALC_SUGERENCIA!$B17&" €",CALC_SUGERENCIA!$F17&" × "&CALC_SUGERENCIA!$B17&" € + "&CALC_SUGERENCIA!$G17&" × "&CALC_SUGERENCIA!$C17&" €")&" → devuelve "&CALC_SUGERENCIA!$H17&" €") -> 16 × 3 € → devuelve 2 € | P17: 1 | Q17: 0 | R17: 0 | S17: =P17*Valor_1+Q17*Valor_2+R17*Valor_3 -> 3 | T17: =MAX(P17*Valor_1,Q17*Valor_2,R17*Valor_3) -> 3 | U17: =MIN(IF(P17=1,Valor_1,9E+99),IF(Q17=1,Valor_2,9E+99),IF(R17=1,Valor_3,9E+99)) -> 3
A18: =Importe_3 -> 50 | B18: ="Solo "&Valor_2&" € ("&Bebida_2&")" -> Solo 5 € (Calimocho) | C18: — | D18: — | E18: 10 | F18: =IF($S18>$A18,"—",E18*Valor_2) -> 50 | G18: — | H18: — | I18: =IF($S18>$A18,"—",SUM(C18,E18,G18)) -> 10 | J18: =IF($S18>$A18,"—",SUM(D18,F18,H18)) -> 50 | K18: =IF($S18>$A18,"—",A18-J18) -> 0 | L18: =IF($S18>$A18,"NO ES POSIBLE",IF(OR(M18="",LEFT(M18,5)="Aviso"),"OK","REVISAR")) -> OK | M18: =IF($S18>$A18,"No cabe ni 1 ficha de cada tipo en "&A18&" €",IF(OR(IF(P18=1,OR(N(C18)<1,N(C18)<>INT(N(C18))),FALSE),IF(Q18=1,OR(N(E18)<1,N(E18)<>INT(N(E18))),FALSE),IF(R18=1,OR(N(G18)<1,N(G18)<>INT(N(G18))),FALSE)),"Falta el nº de fichas (entero, mínimo 1 de cada tipo)",IF(J18>A18,"Las fichas ("&J18&" €) superan el importe",IF(K18>T18,"Devolución mayor que "&T18&" € (ficha más alta): añade fichas",IF(K18>=U18,"Aviso: aún cabría 1 ficha más de "&U18&" €",""))))) | N18: =IF($S18>$A18,"NO ES POSIBLE",IF(CALC_SUGERENCIA!$D18=1,CALC_SUGERENCIA!$F18&" × "&CALC_SUGERENCIA!$B18&" €",CALC_SUGERENCIA!$F18&" × "&CALC_SUGERENCIA!$B18&" € + "&CALC_SUGERENCIA!$G18&" × "&CALC_SUGERENCIA!$C18&" €")&" → devuelve "&CALC_SUGERENCIA!$H18&" €") -> 10 × 5 € → devuelve 0 € | P18: 0 | Q18: 1 | R18: 0 | S18: =P18*Valor_1+Q18*Valor_2+R18*Valor_3 -> 5 | T18: =MAX(P18*Valor_1,Q18*Valor_2,R18*Valor_3) -> 5 | U18: =MIN(IF(P18=1,Valor_1,9E+99),IF(Q18=1,Valor_2,9E+99),IF(R18=1,Valor_3,9E+99)) -> 5
A19: =Importe_3 -> 50 | B19: ="Solo "&Valor_3&" € ("&Bebida_3&")" -> Solo 7 € (Cubata) | C19: — | D19: — | E19: — | F19: — | G19: 7 | H19: =IF($S19>$A19,"—",G19*Valor_3) -> 49 | I19: =IF($S19>$A19,"—",SUM(C19,E19,G19)) -> 7 | J19: =IF($S19>$A19,"—",SUM(D19,F19,H19)) -> 49 | K19: =IF($S19>$A19,"—",A19-J19) -> 1 | L19: =IF($S19>$A19,"NO ES POSIBLE",IF(OR(M19="",LEFT(M19,5)="Aviso"),"OK","REVISAR")) -> OK | M19: =IF($S19>$A19,"No cabe ni 1 ficha de cada tipo en "&A19&" €",IF(OR(IF(P19=1,OR(N(C19)<1,N(C19)<>INT(N(C19))),FALSE),IF(Q19=1,OR(N(E19)<1,N(E19)<>INT(N(E19))),FALSE),IF(R19=1,OR(N(G19)<1,N(G19)<>INT(N(G19))),FALSE)),"Falta el nº de fichas (entero, mínimo 1 de cada tipo)",IF(J19>A19,"Las fichas ("&J19&" €) superan el importe",IF(K19>T19,"Devolución mayor que "&T19&" € (ficha más alta): añade fichas",IF(K19>=U19,"Aviso: aún cabría 1 ficha más de "&U19&" €",""))))) | N19: =IF($S19>$A19,"NO ES POSIBLE",IF(CALC_SUGERENCIA!$D19=1,CALC_SUGERENCIA!$F19&" × "&CALC_SUGERENCIA!$B19&" €",CALC_SUGERENCIA!$F19&" × "&CALC_SUGERENCIA!$B19&" € + "&CALC_SUGERENCIA!$G19&" × "&CALC_SUGERENCIA!$C19&" €")&" → devuelve "&CALC_SUGERENCIA!$H19&" €") -> 7 × 7 € → devuelve 1 € | P19: 0 | Q19: 0 | R19: 1 | S19: =P19*Valor_1+Q19*Valor_2+R19*Valor_3 -> 7 | T19: =MAX(P19*Valor_1,Q19*Valor_2,R19*Valor_3) -> 7 | U19: =MIN(IF(P19=1,Valor_1,9E+99),IF(Q19=1,Valor_2,9E+99),IF(R19=1,Valor_3,9E+99)) -> 7
A20: =Importe_3 -> 50 | B20: =Valor_1&" € + "&Valor_2&" € ("&Bebida_1&" + "&Bebida_2&")" -> 3 € + 5 € (Cerveza + Calimocho) | C20: 6 | D20: =IF($S20>$A20,"—",C20*Valor_1) -> 18 | E20: 6 | F20: =IF($S20>$A20,"—",E20*Valor_2) -> 30 | G20: — | H20: — | I20: =IF($S20>$A20,"—",SUM(C20,E20,G20)) -> 12 | J20: =IF($S20>$A20,"—",SUM(D20,F20,H20)) -> 48 | K20: =IF($S20>$A20,"—",A20-J20) -> 2 | L20: =IF($S20>$A20,"NO ES POSIBLE",IF(OR(M20="",LEFT(M20,5)="Aviso"),"OK","REVISAR")) -> OK | M20: =IF($S20>$A20,"No cabe ni 1 ficha de cada tipo en "&A20&" €",IF(OR(IF(P20=1,OR(N(C20)<1,N(C20)<>INT(N(C20))),FALSE),IF(Q20=1,OR(N(E20)<1,N(E20)<>INT(N(E20))),FALSE),IF(R20=1,OR(N(G20)<1,N(G20)<>INT(N(G20))),FALSE)),"Falta el nº de fichas (entero, mínimo 1 de cada tipo)",IF(J20>A20,"Las fichas ("&J20&" €) superan el importe",IF(K20>T20,"Devolución mayor que "&T20&" € (ficha más alta): añade fichas",IF(K20>=U20,"Aviso: aún cabría 1 ficha más de "&U20&" €",""))))) | N20: =IF($S20>$A20,"NO ES POSIBLE",IF(CALC_SUGERENCIA!$D20=1,CALC_SUGERENCIA!$F20&" × "&CALC_SUGERENCIA!$B20&" €",CALC_SUGERENCIA!$F20&" × "&CALC_SUGERENCIA!$B20&" € + "&CALC_SUGERENCIA!$G20&" × "&CALC_SUGERENCIA!$C20&" €")&" → devuelve "&CALC_SUGERENCIA!$H20&" €") -> 15 × 3 € + 1 × 5 € → devuelve 0 € | P20: 1 | Q20: 1 | R20: 0 | S20: =P20*Valor_1+Q20*Valor_2+R20*Valor_3 -> 8 | T20: =MAX(P20*Valor_1,Q20*Valor_2,R20*Valor_3) -> 5 | U20: =MIN(IF(P20=1,Valor_1,9E+99),IF(Q20=1,Valor_2,9E+99),IF(R20=1,Valor_3,9E+99)) -> 3
A21: =Importe_3 -> 50 | B21: =Valor_1&" € + "&Valor_3&" € ("&Bebida_1&" + "&Bebida_3&")" -> 3 € + 7 € (Cerveza + Cubata) | C21: 5 | D21: =IF($S21>$A21,"—",C21*Valor_1) -> 15 | E21: — | F21: — | G21: 5 | H21: =IF($S21>$A21,"—",G21*Valor_3) -> 35 | I21: =IF($S21>$A21,"—",SUM(C21,E21,G21)) -> 10 | J21: =IF($S21>$A21,"—",SUM(D21,F21,H21)) -> 50 | K21: =IF($S21>$A21,"—",A21-J21) -> 0 | L21: =IF($S21>$A21,"NO ES POSIBLE",IF(OR(M21="",LEFT(M21,5)="Aviso"),"OK","REVISAR")) -> OK | M21: =IF($S21>$A21,"No cabe ni 1 ficha de cada tipo en "&A21&" €",IF(OR(IF(P21=1,OR(N(C21)<1,N(C21)<>INT(N(C21))),FALSE),IF(Q21=1,OR(N(E21)<1,N(E21)<>INT(N(E21))),FALSE),IF(R21=1,OR(N(G21)<1,N(G21)<>INT(N(G21))),FALSE)),"Falta el nº de fichas (entero, mínimo 1 de cada tipo)",IF(J21>A21,"Las fichas ("&J21&" €) superan el importe",IF(K21>T21,"Devolución mayor que "&T21&" € (ficha más alta): añade fichas",IF(K21>=U21,"Aviso: aún cabría 1 ficha más de "&U21&" €",""))))) | N21: =IF($S21>$A21,"NO ES POSIBLE",IF(CALC_SUGERENCIA!$D21=1,CALC_SUGERENCIA!$F21&" × "&CALC_SUGERENCIA!$B21&" €",CALC_SUGERENCIA!$F21&" × "&CALC_SUGERENCIA!$B21&" € + "&CALC_SUGERENCIA!$G21&" × "&CALC_SUGERENCIA!$C21&" €")&" → devuelve "&CALC_SUGERENCIA!$H21&" €") -> 12 × 3 € + 2 × 7 € → devuelve 0 € | P21: 1 | Q21: 0 | R21: 1 | S21: =P21*Valor_1+Q21*Valor_2+R21*Valor_3 -> 10 | T21: =MAX(P21*Valor_1,Q21*Valor_2,R21*Valor_3) -> 7 | U21: =MIN(IF(P21=1,Valor_1,9E+99),IF(Q21=1,Valor_2,9E+99),IF(R21=1,Valor_3,9E+99)) -> 3
A22: =Importe_3 -> 50 | B22: =Valor_2&" € + "&Valor_3&" € ("&Bebida_2&" + "&Bebida_3&")" -> 5 € + 7 € (Calimocho + Cubata) | C22: — | D22: — | E22: 3 | F22: =IF($S22>$A22,"—",E22*Valor_2) -> 15 | G22: 5 | H22: =IF($S22>$A22,"—",G22*Valor_3) -> 35 | I22: =IF($S22>$A22,"—",SUM(C22,E22,G22)) -> 8 | J22: =IF($S22>$A22,"—",SUM(D22,F22,H22)) -> 50 | K22: =IF($S22>$A22,"—",A22-J22) -> 0 | L22: =IF($S22>$A22,"NO ES POSIBLE",IF(OR(M22="",LEFT(M22,5)="Aviso"),"OK","REVISAR")) -> OK | M22: =IF($S22>$A22,"No cabe ni 1 ficha de cada tipo en "&A22&" €",IF(OR(IF(P22=1,OR(N(C22)<1,N(C22)<>INT(N(C22))),FALSE),IF(Q22=1,OR(N(E22)<1,N(E22)<>INT(N(E22))),FALSE),IF(R22=1,OR(N(G22)<1,N(G22)<>INT(N(G22))),FALSE)),"Falta el nº de fichas (entero, mínimo 1 de cada tipo)",IF(J22>A22,"Las fichas ("&J22&" €) superan el importe",IF(K22>T22,"Devolución mayor que "&T22&" € (ficha más alta): añade fichas",IF(K22>=U22,"Aviso: aún cabría 1 ficha más de "&U22&" €",""))))) | N22: =IF($S22>$A22,"NO ES POSIBLE",IF(CALC_SUGERENCIA!$D22=1,CALC_SUGERENCIA!$F22&" × "&CALC_SUGERENCIA!$B22&" €",CALC_SUGERENCIA!$F22&" × "&CALC_SUGERENCIA!$B22&" € + "&CALC_SUGERENCIA!$G22&" × "&CALC_SUGERENCIA!$C22&" €")&" → devuelve "&CALC_SUGERENCIA!$H22&" €") -> 3 × 5 € + 5 × 7 € → devuelve 0 € | P22: 0 | Q22: 1 | R22: 1 | S22: =P22*Valor_1+Q22*Valor_2+R22*Valor_3 -> 12 | T22: =MAX(P22*Valor_1,Q22*Valor_2,R22*Valor_3) -> 7 | U22: =MIN(IF(P22=1,Valor_1,9E+99),IF(Q22=1,Valor_2,9E+99),IF(R22=1,Valor_3,9E+99)) -> 5
A23: =Importe_4 -> 100 | B23: ="Solo "&Valor_1&" € ("&Bebida_1&")" -> Solo 3 € (Cerveza) | C23: 33 | D23: =IF($S23>$A23,"—",C23*Valor_1) -> 99 | E23: — | F23: — | G23: — | H23: — | I23: =IF($S23>$A23,"—",SUM(C23,E23,G23)) -> 33 | J23: =IF($S23>$A23,"—",SUM(D23,F23,H23)) -> 99 | K23: =IF($S23>$A23,"—",A23-J23) -> 1 | L23: =IF($S23>$A23,"NO ES POSIBLE",IF(OR(M23="",LEFT(M23,5)="Aviso"),"OK","REVISAR")) -> OK | M23: =IF($S23>$A23,"No cabe ni 1 ficha de cada tipo en "&A23&" €",IF(OR(IF(P23=1,OR(N(C23)<1,N(C23)<>INT(N(C23))),FALSE),IF(Q23=1,OR(N(E23)<1,N(E23)<>INT(N(E23))),FALSE),IF(R23=1,OR(N(G23)<1,N(G23)<>INT(N(G23))),FALSE)),"Falta el nº de fichas (entero, mínimo 1 de cada tipo)",IF(J23>A23,"Las fichas ("&J23&" €) superan el importe",IF(K23>T23,"Devolución mayor que "&T23&" € (ficha más alta): añade fichas",IF(K23>=U23,"Aviso: aún cabría 1 ficha más de "&U23&" €",""))))) | N23: =IF($S23>$A23,"NO ES POSIBLE",IF(CALC_SUGERENCIA!$D23=1,CALC_SUGERENCIA!$F23&" × "&CALC_SUGERENCIA!$B23&" €",CALC_SUGERENCIA!$F23&" × "&CALC_SUGERENCIA!$B23&" € + "&CALC_SUGERENCIA!$G23&" × "&CALC_SUGERENCIA!$C23&" €")&" → devuelve "&CALC_SUGERENCIA!$H23&" €") -> 33 × 3 € → devuelve 1 € | P23: 1 | Q23: 0 | R23: 0 | S23: =P23*Valor_1+Q23*Valor_2+R23*Valor_3 -> 3 | T23: =MAX(P23*Valor_1,Q23*Valor_2,R23*Valor_3) -> 3 | U23: =MIN(IF(P23=1,Valor_1,9E+99),IF(Q23=1,Valor_2,9E+99),IF(R23=1,Valor_3,9E+99)) -> 3
A24: =Importe_4 -> 100 | B24: ="Solo "&Valor_2&" € ("&Bebida_2&")" -> Solo 5 € (Calimocho) | C24: — | D24: — | E24: 20 | F24: =IF($S24>$A24,"—",E24*Valor_2) -> 100 | G24: — | H24: — | I24: =IF($S24>$A24,"—",SUM(C24,E24,G24)) -> 20 | J24: =IF($S24>$A24,"—",SUM(D24,F24,H24)) -> 100 | K24: =IF($S24>$A24,"—",A24-J24) -> 0 | L24: =IF($S24>$A24,"NO ES POSIBLE",IF(OR(M24="",LEFT(M24,5)="Aviso"),"OK","REVISAR")) -> OK | M24: =IF($S24>$A24,"No cabe ni 1 ficha de cada tipo en "&A24&" €",IF(OR(IF(P24=1,OR(N(C24)<1,N(C24)<>INT(N(C24))),FALSE),IF(Q24=1,OR(N(E24)<1,N(E24)<>INT(N(E24))),FALSE),IF(R24=1,OR(N(G24)<1,N(G24)<>INT(N(G24))),FALSE)),"Falta el nº de fichas (entero, mínimo 1 de cada tipo)",IF(J24>A24,"Las fichas ("&J24&" €) superan el importe",IF(K24>T24,"Devolución mayor que "&T24&" € (ficha más alta): añade fichas",IF(K24>=U24,"Aviso: aún cabría 1 ficha más de "&U24&" €",""))))) | N24: =IF($S24>$A24,"NO ES POSIBLE",IF(CALC_SUGERENCIA!$D24=1,CALC_SUGERENCIA!$F24&" × "&CALC_SUGERENCIA!$B24&" €",CALC_SUGERENCIA!$F24&" × "&CALC_SUGERENCIA!$B24&" € + "&CALC_SUGERENCIA!$G24&" × "&CALC_SUGERENCIA!$C24&" €")&" → devuelve "&CALC_SUGERENCIA!$H24&" €") -> 20 × 5 € → devuelve 0 € | P24: 0 | Q24: 1 | R24: 0 | S24: =P24*Valor_1+Q24*Valor_2+R24*Valor_3 -> 5 | T24: =MAX(P24*Valor_1,Q24*Valor_2,R24*Valor_3) -> 5 | U24: =MIN(IF(P24=1,Valor_1,9E+99),IF(Q24=1,Valor_2,9E+99),IF(R24=1,Valor_3,9E+99)) -> 5
A25: =Importe_4 -> 100 | B25: ="Solo "&Valor_3&" € ("&Bebida_3&")" -> Solo 7 € (Cubata) | C25: — | D25: — | E25: — | F25: — | G25: 14 | H25: =IF($S25>$A25,"—",G25*Valor_3) -> 98 | I25: =IF($S25>$A25,"—",SUM(C25,E25,G25)) -> 14 | J25: =IF($S25>$A25,"—",SUM(D25,F25,H25)) -> 98 | K25: =IF($S25>$A25,"—",A25-J25) -> 2 | L25: =IF($S25>$A25,"NO ES POSIBLE",IF(OR(M25="",LEFT(M25,5)="Aviso"),"OK","REVISAR")) -> OK | M25: =IF($S25>$A25,"No cabe ni 1 ficha de cada tipo en "&A25&" €",IF(OR(IF(P25=1,OR(N(C25)<1,N(C25)<>INT(N(C25))),FALSE),IF(Q25=1,OR(N(E25)<1,N(E25)<>INT(N(E25))),FALSE),IF(R25=1,OR(N(G25)<1,N(G25)<>INT(N(G25))),FALSE)),"Falta el nº de fichas (entero, mínimo 1 de cada tipo)",IF(J25>A25,"Las fichas ("&J25&" €) superan el importe",IF(K25>T25,"Devolución mayor que "&T25&" € (ficha más alta): añade fichas",IF(K25>=U25,"Aviso: aún cabría 1 ficha más de "&U25&" €",""))))) | N25: =IF($S25>$A25,"NO ES POSIBLE",IF(CALC_SUGERENCIA!$D25=1,CALC_SUGERENCIA!$F25&" × "&CALC_SUGERENCIA!$B25&" €",CALC_SUGERENCIA!$F25&" × "&CALC_SUGERENCIA!$B25&" € + "&CALC_SUGERENCIA!$G25&" × "&CALC_SUGERENCIA!$C25&" €")&" → devuelve "&CALC_SUGERENCIA!$H25&" €") -> 14 × 7 € → devuelve 2 € | P25: 0 | Q25: 0 | R25: 1 | S25: =P25*Valor_1+Q25*Valor_2+R25*Valor_3 -> 7 | T25: =MAX(P25*Valor_1,Q25*Valor_2,R25*Valor_3) -> 7 | U25: =MIN(IF(P25=1,Valor_1,9E+99),IF(Q25=1,Valor_2,9E+99),IF(R25=1,Valor_3,9E+99)) -> 7
A26: =Importe_4 -> 100 | B26: =Valor_1&" € + "&Valor_2&" € ("&Bebida_1&" + "&Bebida_2&")" -> 3 € + 5 € (Cerveza + Calimocho) | C26: 8 | D26: =IF($S26>$A26,"—",C26*Valor_1) -> 24 | E26: 15 | F26: =IF($S26>$A26,"—",E26*Valor_2) -> 75 | G26: — | H26: — | I26: =IF($S26>$A26,"—",SUM(C26,E26,G26)) -> 23 | J26: =IF($S26>$A26,"—",SUM(D26,F26,H26)) -> 99 | K26: =IF($S26>$A26,"—",A26-J26) -> 1 | L26: =IF($S26>$A26,"NO ES POSIBLE",IF(OR(M26="",LEFT(M26,5)="Aviso"),"OK","REVISAR")) -> OK | M26: =IF($S26>$A26,"No cabe ni 1 ficha de cada tipo en "&A26&" €",IF(OR(IF(P26=1,OR(N(C26)<1,N(C26)<>INT(N(C26))),FALSE),IF(Q26=1,OR(N(E26)<1,N(E26)<>INT(N(E26))),FALSE),IF(R26=1,OR(N(G26)<1,N(G26)<>INT(N(G26))),FALSE)),"Falta el nº de fichas (entero, mínimo 1 de cada tipo)",IF(J26>A26,"Las fichas ("&J26&" €) superan el importe",IF(K26>T26,"Devolución mayor que "&T26&" € (ficha más alta): añade fichas",IF(K26>=U26,"Aviso: aún cabría 1 ficha más de "&U26&" €",""))))) | N26: =IF($S26>$A26,"NO ES POSIBLE",IF(CALC_SUGERENCIA!$D26=1,CALC_SUGERENCIA!$F26&" × "&CALC_SUGERENCIA!$B26&" €",CALC_SUGERENCIA!$F26&" × "&CALC_SUGERENCIA!$B26&" € + "&CALC_SUGERENCIA!$G26&" × "&CALC_SUGERENCIA!$C26&" €")&" → devuelve "&CALC_SUGERENCIA!$H26&" €") -> 30 × 3 € + 2 × 5 € → devuelve 0 € | P26: 1 | Q26: 1 | R26: 0 | S26: =P26*Valor_1+Q26*Valor_2+R26*Valor_3 -> 8 | T26: =MAX(P26*Valor_1,Q26*Valor_2,R26*Valor_3) -> 5 | U26: =MIN(IF(P26=1,Valor_1,9E+99),IF(Q26=1,Valor_2,9E+99),IF(R26=1,Valor_3,9E+99)) -> 3
A27: =Importe_4 -> 100 | B27: =Valor_1&" € + "&Valor_3&" € ("&Bebida_1&" + "&Bebida_3&")" -> 3 € + 7 € (Cerveza + Cubata) | C27: 10 | D27: =IF($S27>$A27,"—",C27*Valor_1) -> 30 | E27: — | F27: — | G27: 10 | H27: =IF($S27>$A27,"—",G27*Valor_3) -> 70 | I27: =IF($S27>$A27,"—",SUM(C27,E27,G27)) -> 20 | J27: =IF($S27>$A27,"—",SUM(D27,F27,H27)) -> 100 | K27: =IF($S27>$A27,"—",A27-J27) -> 0 | L27: =IF($S27>$A27,"NO ES POSIBLE",IF(OR(M27="",LEFT(M27,5)="Aviso"),"OK","REVISAR")) -> OK | M27: =IF($S27>$A27,"No cabe ni 1 ficha de cada tipo en "&A27&" €",IF(OR(IF(P27=1,OR(N(C27)<1,N(C27)<>INT(N(C27))),FALSE),IF(Q27=1,OR(N(E27)<1,N(E27)<>INT(N(E27))),FALSE),IF(R27=1,OR(N(G27)<1,N(G27)<>INT(N(G27))),FALSE)),"Falta el nº de fichas (entero, mínimo 1 de cada tipo)",IF(J27>A27,"Las fichas ("&J27&" €) superan el importe",IF(K27>T27,"Devolución mayor que "&T27&" € (ficha más alta): añade fichas",IF(K27>=U27,"Aviso: aún cabría 1 ficha más de "&U27&" €",""))))) | N27: =IF($S27>$A27,"NO ES POSIBLE",IF(CALC_SUGERENCIA!$D27=1,CALC_SUGERENCIA!$F27&" × "&CALC_SUGERENCIA!$B27&" €",CALC_SUGERENCIA!$F27&" × "&CALC_SUGERENCIA!$B27&" € + "&CALC_SUGERENCIA!$G27&" × "&CALC_SUGERENCIA!$C27&" €")&" → devuelve "&CALC_SUGERENCIA!$H27&" €") -> 31 × 3 € + 1 × 7 € → devuelve 0 € | P27: 1 | Q27: 0 | R27: 1 | S27: =P27*Valor_1+Q27*Valor_2+R27*Valor_3 -> 10 | T27: =MAX(P27*Valor_1,Q27*Valor_2,R27*Valor_3) -> 7 | U27: =MIN(IF(P27=1,Valor_1,9E+99),IF(Q27=1,Valor_2,9E+99),IF(R27=1,Valor_3,9E+99)) -> 3
A28: =Importe_4 -> 100 | B28: =Valor_2&" € + "&Valor_3&" € ("&Bebida_2&" + "&Bebida_3&")" -> 5 € + 7 € (Calimocho + Cubata) | C28: — | D28: — | E28: 13 | F28: =IF($S28>$A28,"—",E28*Valor_2) -> 65 | G28: 5 | H28: =IF($S28>$A28,"—",G28*Valor_3) -> 35 | I28: =IF($S28>$A28,"—",SUM(C28,E28,G28)) -> 18 | J28: =IF($S28>$A28,"—",SUM(D28,F28,H28)) -> 100 | K28: =IF($S28>$A28,"—",A28-J28) -> 0 | L28: =IF($S28>$A28,"NO ES POSIBLE",IF(OR(M28="",LEFT(M28,5)="Aviso"),"OK","REVISAR")) -> OK | M28: =IF($S28>$A28,"No cabe ni 1 ficha de cada tipo en "&A28&" €",IF(OR(IF(P28=1,OR(N(C28)<1,N(C28)<>INT(N(C28))),FALSE),IF(Q28=1,OR(N(E28)<1,N(E28)<>INT(N(E28))),FALSE),IF(R28=1,OR(N(G28)<1,N(G28)<>INT(N(G28))),FALSE)),"Falta el nº de fichas (entero, mínimo 1 de cada tipo)",IF(J28>A28,"Las fichas ("&J28&" €) superan el importe",IF(K28>T28,"Devolución mayor que "&T28&" € (ficha más alta): añade fichas",IF(K28>=U28,"Aviso: aún cabría 1 ficha más de "&U28&" €",""))))) | N28: =IF($S28>$A28,"NO ES POSIBLE",IF(CALC_SUGERENCIA!$D28=1,CALC_SUGERENCIA!$F28&" × "&CALC_SUGERENCIA!$B28&" €",CALC_SUGERENCIA!$F28&" × "&CALC_SUGERENCIA!$B28&" € + "&CALC_SUGERENCIA!$G28&" × "&CALC_SUGERENCIA!$C28&" €")&" → devuelve "&CALC_SUGERENCIA!$H28&" €") -> 13 × 5 € + 5 × 7 € → devuelve 0 € | P28: 0 | Q28: 1 | R28: 1 | S28: =P28*Valor_1+Q28*Valor_2+R28*Valor_3 -> 12 | T28: =MAX(P28*Valor_1,Q28*Valor_2,R28*Valor_3) -> 7 | U28: =MIN(IF(P28=1,Valor_1,9E+99),IF(Q28=1,Valor_2,9E+99),IF(R28=1,Valor_3,9E+99)) -> 5
A29: =Importe_5 -> 200 | B29: ="Solo "&Valor_1&" € ("&Bebida_1&")" -> Solo 3 € (Cerveza) | C29: 66 | D29: =IF($S29>$A29,"—",C29*Valor_1) -> 198 | E29: — | F29: — | G29: — | H29: — | I29: =IF($S29>$A29,"—",SUM(C29,E29,G29)) -> 66 | J29: =IF($S29>$A29,"—",SUM(D29,F29,H29)) -> 198 | K29: =IF($S29>$A29,"—",A29-J29) -> 2 | L29: =IF($S29>$A29,"NO ES POSIBLE",IF(OR(M29="",LEFT(M29,5)="Aviso"),"OK","REVISAR")) -> OK | M29: =IF($S29>$A29,"No cabe ni 1 ficha de cada tipo en "&A29&" €",IF(OR(IF(P29=1,OR(N(C29)<1,N(C29)<>INT(N(C29))),FALSE),IF(Q29=1,OR(N(E29)<1,N(E29)<>INT(N(E29))),FALSE),IF(R29=1,OR(N(G29)<1,N(G29)<>INT(N(G29))),FALSE)),"Falta el nº de fichas (entero, mínimo 1 de cada tipo)",IF(J29>A29,"Las fichas ("&J29&" €) superan el importe",IF(K29>T29,"Devolución mayor que "&T29&" € (ficha más alta): añade fichas",IF(K29>=U29,"Aviso: aún cabría 1 ficha más de "&U29&" €",""))))) | N29: =IF($S29>$A29,"NO ES POSIBLE",IF(CALC_SUGERENCIA!$D29=1,CALC_SUGERENCIA!$F29&" × "&CALC_SUGERENCIA!$B29&" €",CALC_SUGERENCIA!$F29&" × "&CALC_SUGERENCIA!$B29&" € + "&CALC_SUGERENCIA!$G29&" × "&CALC_SUGERENCIA!$C29&" €")&" → devuelve "&CALC_SUGERENCIA!$H29&" €") -> 66 × 3 € → devuelve 2 € | P29: 1 | Q29: 0 | R29: 0 | S29: =P29*Valor_1+Q29*Valor_2+R29*Valor_3 -> 3 | T29: =MAX(P29*Valor_1,Q29*Valor_2,R29*Valor_3) -> 3 | U29: =MIN(IF(P29=1,Valor_1,9E+99),IF(Q29=1,Valor_2,9E+99),IF(R29=1,Valor_3,9E+99)) -> 3
A30: =Importe_5 -> 200 | B30: ="Solo "&Valor_2&" € ("&Bebida_2&")" -> Solo 5 € (Calimocho) | C30: — | D30: — | E30: 40 | F30: =IF($S30>$A30,"—",E30*Valor_2) -> 200 | G30: — | H30: — | I30: =IF($S30>$A30,"—",SUM(C30,E30,G30)) -> 40 | J30: =IF($S30>$A30,"—",SUM(D30,F30,H30)) -> 200 | K30: =IF($S30>$A30,"—",A30-J30) -> 0 | L30: =IF($S30>$A30,"NO ES POSIBLE",IF(OR(M30="",LEFT(M30,5)="Aviso"),"OK","REVISAR")) -> OK | M30: =IF($S30>$A30,"No cabe ni 1 ficha de cada tipo en "&A30&" €",IF(OR(IF(P30=1,OR(N(C30)<1,N(C30)<>INT(N(C30))),FALSE),IF(Q30=1,OR(N(E30)<1,N(E30)<>INT(N(E30))),FALSE),IF(R30=1,OR(N(G30)<1,N(G30)<>INT(N(G30))),FALSE)),"Falta el nº de fichas (entero, mínimo 1 de cada tipo)",IF(J30>A30,"Las fichas ("&J30&" €) superan el importe",IF(K30>T30,"Devolución mayor que "&T30&" € (ficha más alta): añade fichas",IF(K30>=U30,"Aviso: aún cabría 1 ficha más de "&U30&" €",""))))) | N30: =IF($S30>$A30,"NO ES POSIBLE",IF(CALC_SUGERENCIA!$D30=1,CALC_SUGERENCIA!$F30&" × "&CALC_SUGERENCIA!$B30&" €",CALC_SUGERENCIA!$F30&" × "&CALC_SUGERENCIA!$B30&" € + "&CALC_SUGERENCIA!$G30&" × "&CALC_SUGERENCIA!$C30&" €")&" → devuelve "&CALC_SUGERENCIA!$H30&" €") -> 40 × 5 € → devuelve 0 € | P30: 0 | Q30: 1 | R30: 0 | S30: =P30*Valor_1+Q30*Valor_2+R30*Valor_3 -> 5 | T30: =MAX(P30*Valor_1,Q30*Valor_2,R30*Valor_3) -> 5 | U30: =MIN(IF(P30=1,Valor_1,9E+99),IF(Q30=1,Valor_2,9E+99),IF(R30=1,Valor_3,9E+99)) -> 5
A31: =Importe_5 -> 200 | B31: ="Solo "&Valor_3&" € ("&Bebida_3&")" -> Solo 7 € (Cubata) | C31: — | D31: — | E31: — | F31: — | G31: 28 | H31: =IF($S31>$A31,"—",G31*Valor_3) -> 196 | I31: =IF($S31>$A31,"—",SUM(C31,E31,G31)) -> 28 | J31: =IF($S31>$A31,"—",SUM(D31,F31,H31)) -> 196 | K31: =IF($S31>$A31,"—",A31-J31) -> 4 | L31: =IF($S31>$A31,"NO ES POSIBLE",IF(OR(M31="",LEFT(M31,5)="Aviso"),"OK","REVISAR")) -> OK | M31: =IF($S31>$A31,"No cabe ni 1 ficha de cada tipo en "&A31&" €",IF(OR(IF(P31=1,OR(N(C31)<1,N(C31)<>INT(N(C31))),FALSE),IF(Q31=1,OR(N(E31)<1,N(E31)<>INT(N(E31))),FALSE),IF(R31=1,OR(N(G31)<1,N(G31)<>INT(N(G31))),FALSE)),"Falta el nº de fichas (entero, mínimo 1 de cada tipo)",IF(J31>A31,"Las fichas ("&J31&" €) superan el importe",IF(K31>T31,"Devolución mayor que "&T31&" € (ficha más alta): añade fichas",IF(K31>=U31,"Aviso: aún cabría 1 ficha más de "&U31&" €",""))))) | N31: =IF($S31>$A31,"NO ES POSIBLE",IF(CALC_SUGERENCIA!$D31=1,CALC_SUGERENCIA!$F31&" × "&CALC_SUGERENCIA!$B31&" €",CALC_SUGERENCIA!$F31&" × "&CALC_SUGERENCIA!$B31&" € + "&CALC_SUGERENCIA!$G31&" × "&CALC_SUGERENCIA!$C31&" €")&" → devuelve "&CALC_SUGERENCIA!$H31&" €") -> 28 × 7 € → devuelve 4 € | P31: 0 | Q31: 0 | R31: 1 | S31: =P31*Valor_1+Q31*Valor_2+R31*Valor_3 -> 7 | T31: =MAX(P31*Valor_1,Q31*Valor_2,R31*Valor_3) -> 7 | U31: =MIN(IF(P31=1,Valor_1,9E+99),IF(Q31=1,Valor_2,9E+99),IF(R31=1,Valor_3,9E+99)) -> 7
A32: =Importe_5 -> 200 | B32: =Valor_1&" € + "&Valor_2&" € ("&Bebida_1&" + "&Bebida_2&")" -> 3 € + 5 € (Cerveza + Calimocho) | C32: 16 | D32: =IF($S32>$A32,"—",C32*Valor_1) -> 48 | E32: 30 | F32: =IF($S32>$A32,"—",E32*Valor_2) -> 150 | G32: — | H32: — | I32: =IF($S32>$A32,"—",SUM(C32,E32,G32)) -> 46 | J32: =IF($S32>$A32,"—",SUM(D32,F32,H32)) -> 198 | K32: =IF($S32>$A32,"—",A32-J32) -> 2 | L32: =IF($S32>$A32,"NO ES POSIBLE",IF(OR(M32="",LEFT(M32,5)="Aviso"),"OK","REVISAR")) -> OK | M32: =IF($S32>$A32,"No cabe ni 1 ficha de cada tipo en "&A32&" €",IF(OR(IF(P32=1,OR(N(C32)<1,N(C32)<>INT(N(C32))),FALSE),IF(Q32=1,OR(N(E32)<1,N(E32)<>INT(N(E32))),FALSE),IF(R32=1,OR(N(G32)<1,N(G32)<>INT(N(G32))),FALSE)),"Falta el nº de fichas (entero, mínimo 1 de cada tipo)",IF(J32>A32,"Las fichas ("&J32&" €) superan el importe",IF(K32>T32,"Devolución mayor que "&T32&" € (ficha más alta): añade fichas",IF(K32>=U32,"Aviso: aún cabría 1 ficha más de "&U32&" €",""))))) | N32: =IF($S32>$A32,"NO ES POSIBLE",IF(CALC_SUGERENCIA!$D32=1,CALC_SUGERENCIA!$F32&" × "&CALC_SUGERENCIA!$B32&" €",CALC_SUGERENCIA!$F32&" × "&CALC_SUGERENCIA!$B32&" € + "&CALC_SUGERENCIA!$G32&" × "&CALC_SUGERENCIA!$C32&" €")&" → devuelve "&CALC_SUGERENCIA!$H32&" €") -> 65 × 3 € + 1 × 5 € → devuelve 0 € | P32: 1 | Q32: 1 | R32: 0 | S32: =P32*Valor_1+Q32*Valor_2+R32*Valor_3 -> 8 | T32: =MAX(P32*Valor_1,Q32*Valor_2,R32*Valor_3) -> 5 | U32: =MIN(IF(P32=1,Valor_1,9E+99),IF(Q32=1,Valor_2,9E+99),IF(R32=1,Valor_3,9E+99)) -> 3
A33: =Importe_5 -> 200 | B33: =Valor_1&" € + "&Valor_3&" € ("&Bebida_1&" + "&Bebida_3&")" -> 3 € + 7 € (Cerveza + Cubata) | C33: 15 | D33: =IF($S33>$A33,"—",C33*Valor_1) -> 45 | E33: — | F33: — | G33: 22 | H33: =IF($S33>$A33,"—",G33*Valor_3) -> 154 | I33: =IF($S33>$A33,"—",SUM(C33,E33,G33)) -> 37 | J33: =IF($S33>$A33,"—",SUM(D33,F33,H33)) -> 199 | K33: =IF($S33>$A33,"—",A33-J33) -> 1 | L33: =IF($S33>$A33,"NO ES POSIBLE",IF(OR(M33="",LEFT(M33,5)="Aviso"),"OK","REVISAR")) -> OK | M33: =IF($S33>$A33,"No cabe ni 1 ficha de cada tipo en "&A33&" €",IF(OR(IF(P33=1,OR(N(C33)<1,N(C33)<>INT(N(C33))),FALSE),IF(Q33=1,OR(N(E33)<1,N(E33)<>INT(N(E33))),FALSE),IF(R33=1,OR(N(G33)<1,N(G33)<>INT(N(G33))),FALSE)),"Falta el nº de fichas (entero, mínimo 1 de cada tipo)",IF(J33>A33,"Las fichas ("&J33&" €) superan el importe",IF(K33>T33,"Devolución mayor que "&T33&" € (ficha más alta): añade fichas",IF(K33>=U33,"Aviso: aún cabría 1 ficha más de "&U33&" €",""))))) | N33: =IF($S33>$A33,"NO ES POSIBLE",IF(CALC_SUGERENCIA!$D33=1,CALC_SUGERENCIA!$F33&" × "&CALC_SUGERENCIA!$B33&" €",CALC_SUGERENCIA!$F33&" × "&CALC_SUGERENCIA!$B33&" € + "&CALC_SUGERENCIA!$G33&" × "&CALC_SUGERENCIA!$C33&" €")&" → devuelve "&CALC_SUGERENCIA!$H33&" €") -> 62 × 3 € + 2 × 7 € → devuelve 0 € | P33: 1 | Q33: 0 | R33: 1 | S33: =P33*Valor_1+Q33*Valor_2+R33*Valor_3 -> 10 | T33: =MAX(P33*Valor_1,Q33*Valor_2,R33*Valor_3) -> 7 | U33: =MIN(IF(P33=1,Valor_1,9E+99),IF(Q33=1,Valor_2,9E+99),IF(R33=1,Valor_3,9E+99)) -> 3
A34: =Importe_5 -> 200 | B34: =Valor_2&" € + "&Valor_3&" € ("&Bebida_2&" + "&Bebida_3&")" -> 5 € + 7 € (Calimocho + Cubata) | C34: — | D34: — | E34: 19 | F34: =IF($S34>$A34,"—",E34*Valor_2) -> 95 | G34: 15 | H34: =IF($S34>$A34,"—",G34*Valor_3) -> 105 | I34: =IF($S34>$A34,"—",SUM(C34,E34,G34)) -> 34 | J34: =IF($S34>$A34,"—",SUM(D34,F34,H34)) -> 200 | K34: =IF($S34>$A34,"—",A34-J34) -> 0 | L34: =IF($S34>$A34,"NO ES POSIBLE",IF(OR(M34="",LEFT(M34,5)="Aviso"),"OK","REVISAR")) -> OK | M34: =IF($S34>$A34,"No cabe ni 1 ficha de cada tipo en "&A34&" €",IF(OR(IF(P34=1,OR(N(C34)<1,N(C34)<>INT(N(C34))),FALSE),IF(Q34=1,OR(N(E34)<1,N(E34)<>INT(N(E34))),FALSE),IF(R34=1,OR(N(G34)<1,N(G34)<>INT(N(G34))),FALSE)),"Falta el nº de fichas (entero, mínimo 1 de cada tipo)",IF(J34>A34,"Las fichas ("&J34&" €) superan el importe",IF(K34>T34,"Devolución mayor que "&T34&" € (ficha más alta): añade fichas",IF(K34>=U34,"Aviso: aún cabría 1 ficha más de "&U34&" €",""))))) | N34: =IF($S34>$A34,"NO ES POSIBLE",IF(CALC_SUGERENCIA!$D34=1,CALC_SUGERENCIA!$F34&" × "&CALC_SUGERENCIA!$B34&" €",CALC_SUGERENCIA!$F34&" × "&CALC_SUGERENCIA!$B34&" € + "&CALC_SUGERENCIA!$G34&" × "&CALC_SUGERENCIA!$C34&" €")&" → devuelve "&CALC_SUGERENCIA!$H34&" €") -> 33 × 5 € + 5 × 7 € → devuelve 0 € | P34: 0 | Q34: 1 | R34: 1 | S34: =P34*Valor_1+Q34*Valor_2+R34*Valor_3 -> 12 | T34: =MAX(P34*Valor_1,Q34*Valor_2,R34*Valor_3) -> 7 | U34: =MIN(IF(P34=1,Valor_1,9E+99),IF(Q34=1,Valor_2,9E+99),IF(R34=1,Valor_3,9E+99)) -> 5

Sheet CALC_SUGERENCIA
A1: Cálculo de la sugerencia óptima. Para cada fila prueba a = 1..250 fichas del primer tipo y el máximo del segundo.
A2: Puntuación = devolución·100000 + (10000 − nº fichas) → la mínima = menor devolución y, a igualdad, más fichas.
A4: Importe | B4: Valor A | C4: Valor B | D4: Nº tipos | E4: Mejor puntuación | F4: Fichas A | G4: Fichas B | H4: Devolución | J4: 1 | K4: 2 | L4: 3 | M4: 4 | N4: 5 | O4: 6 | P4: 7 | Q4: 8 | R4: 9 | S4: 10 | T4: 11 | U4: 12 | V4: 13 | W4: 14 | X4: 15 | Y4: 16 | Z4: 17 | AA4: 18 | AB4: 19 | AC4: 20 | AD4: 21 | AE4: 22 | AF4: 23 | AG4: 24 | AH4: 25 | AI4: 26 | AJ4: 27 | AK4: 28 | AL4: 29 | AM4: 30 | AN4: 31 | AO4: 32 | AP4: 33 | AQ4: 34 | AR4: 35 | AS4: 36 | AT4: 37 | AU4: 38 | AV4: 39 | AW4: 40 | AX4: 41 | AY4: 42 | AZ4: 43 | BA4: 44 | BB4: 45 | BC4: 46 | BD4: 47 | BE4: 48 | BF4: 49 | BG4: 50 | BH4: 51 | BI4: 52 | BJ4: 53 | BK4: 54 | BL4: 55 | BM4: 56 | BN4: 57 | BO4: 58 | BP4: 59 | BQ4: 60 | BR4: 61 | BS4: 62 | BT4: 63 | BU4: 64 | BV4: 65 | BW4: 66 | BX4: 67 | BY4: 68 | BZ4: 69 | CA4: 70 | CB4: 71 | CC4: 72 | CD4: 73 | CE4: 74 | CF4: 75 | CG4: 76 | CH4: 77 | CI4: 78 | CJ4: 79 | CK4: 80 | CL4: 81 | CM4: 82 | CN4: 83 | CO4: 84 | CP4: 85 | CQ4: 86 | CR4: 87 | CS4: 88 | CT4: 89 | CU4: 90 | CV4: 91 | CW4: 92 | CX4: 93 | CY4: 94 | CZ4: 95 | DA4: 96 | DB4: 97 | DC4: 98 | DD4: 99 | DE4: 100 | DF4: 101 | DG4: 102 | DH4: 103 | DI4: 104 | DJ4: 105 | DK4: 106 | DL4: 107 | DM4: 108 | DN4: 109 | DO4: 110 | DP4: 111 | DQ4: 112 | DR4: 113 | DS4: 114 | DT4: 115 | DU4: 116 | DV4: 117 | DW4: 118 | DX4: 119 | DY4: 120 | DZ4: 121 | EA4: 122 | EB4: 123 | EC4: 124 | ED4: 125 | EE4: 126 | EF4: 127 | EG4: 128 | EH4: 129 | EI4: 130 | EJ4: 131 | EK4: 132 | EL4: 133 | EM4: 134 | EN4: 135 | EO4: 136 | EP4: 137 | EQ4: 138 | ER4: 139 | ES4: 140 | ET4: 141 | EU4: 142 | EV4: 143 | EW4: 144 | EX4: 145 | EY4: 146 | EZ4: 147 | FA4: 148 | FB4: 149 | FC4: 150 | FD4: 151 | FE4: 152 | FF4: 153 | FG4: 154 | FH4: 155 | FI4: 156 | FJ4: 157 | FK4: 158 | FL4: 159 | FM4: 160 | FN4: 161 | FO4: 162 | FP4: 163 | FQ4: 164 | FR4: 165 | FS4: 166 | FT4: 167 | FU4: 168 | FV4: 169 | FW4: 170 | FX4: 171 | FY4: 172 | FZ4: 173 | GA4: 174 | GB4: 175 | GC4: 176 | GD4: 177 | GE4: 178 | GF4: 179 | GG4: 180 | GH4: 181 | GI4: 182 | GJ4: 183 | GK4: 184 | GL4: 185 | GM4: 186 | GN4: 187 | GO4: 188 | GP4: 189 | GQ4: 190 | GR4: 191 | GS4: 192 | GT4: 193 | GU4: 194 | GV4: 195 | GW4: 196 | GX4: 197 | GY4: 198 | GZ4: 199 | HA4: 200 | HB4: 201 | HC4: 202 | HD4: 203 | HE4: 204 | HF4: 205 | HG4: 206 | HH4: 207 | HI4: 208 | HJ4: 209 | HK4: 210 | HL4: 211 | HM4: 212 | HN4: 213 | HO4: 214 | HP4: 215 | HQ4: 216 | HR4: 217 | HS4: 218 | HT4: 219 | HU4: 220 | HV4: 221 | HW4: 222 | HX4: 223 | HY4: 224 | HZ4: 225 | IA4: 226 | IB4: 227 | IC4: 228 | ID4: 229 | IE4: 230 | IF4: 231 | IG4: 232 | IH4: 233 | II4: 234 | IJ4: 235 | IK4: 236 | IL4: 237 | IM4: 238 | IN4: 239 | IO4: 240 | IP4: 241 | IQ4: 242 | IR4: 243 | IS4: 244 | IT4: 245 | IU4: 246 | IV4: 247 | IW4: 248 | IX4: 249 | IY4: 250
A5: =CAMBIOS!A5 -> 10 | B5: =IF(D5=1,CAMBIOS!P5*Valor_1+CAMBIOS!Q5*Valor_2+CAMBIOS!R5*Valor_3,IF(CAMBIOS!P5=1,Valor_1,Valor_2)) -> 3 | C5: =IF(D5=1,0,IF(CAMBIOS!R5=1,Valor_3,Valor_2)) -> 0 | D5: =CAMBIOS!P5+CAMBIOS!Q5+CAMBIOS!R5 -> 1 | E5: =MIN(J5:IY5) -> 99999999 | F5: =IF(D5=1,INT(A5/B5),IF(E5>=99999999,0,MATCH(E5,J5:IY5,0))) -> 3 | G5: =IF(D5=1,0,IF(E5>=99999999,0,INT((A5-F5*B5)/C5))) -> 0 | H5: =A5-F5*B5-G5*C5 -> 1 | J5: =IF(OR($D5<>2,J$4*$B5+$C5>$A5),99999999,(($A5-J$4*$B5)-INT(($A5-J$4*$B5)/$C5)*$C5)*100000+10000-J$4-INT(($A5-J$4*$B5)/$C5)) -> 99999999 | K5: =IF(OR($D5<>2,K$4*$B5+$C5>$A5),99999999,(($A5-K$4*$B5)-INT(($A5-K$4*$B5)/$C5)*$C5)*100000+10000-K$4-INT(($A5-K$4*$B5)/$C5)) -> 99999999 | L5: =IF(OR($D5<>2,L$4*$B5+$C5>$A5),99999999,(($A5-L$4*$B5)-INT(($A5-L$4*$B5)/$C5)*$C5)*100000+10000-L$4-INT(($A5-L$4*$B5)/$C5)) -> 99999999 | M5: =IF(OR($D5<>2,M$4*$B5+$C5>$A5),99999999,(($A5-M$4*$B5)-INT(($A5-M$4*$B5)/$C5)*$C5)*100000+10000-M$4-INT(($A5-M$4*$B5)/$C5)) -> 99999999 | N5: =IF(OR($D5<>2,N$4*$B5+$C5>$A5),99999999,(($A5-N$4*$B5)-INT(($A5-N$4*$B5)/$C5)*$C5)*100000+10000-N$4-INT(($A5-N$4*$B5)/$C5)) -> 99999999 | O5: =IF(OR($D5<>2,O$4*$B5+$C5>$A5),99999999,(($A5-O$4*$B5)-INT(($A5-O$4*$B5)/$C5)*$C5)*100000+10000-O$4-INT(($A5-O$4*$B5)/$C5)) -> 99999999 | P5: =IF(OR($D5<>2,P$4*$B5+$C5>$A5),99999999,(($A5-P$4*$B5)-INT(($A5-P$4*$B5)/$C5)*$C5)*100000+10000-P$4-INT(($A5-P$4*$B5)/$C5)) -> 99999999 | Q5: =IF(OR($D5<>2,Q$4*$B5+$C5>$A5),99999999,(($A5-Q$4*$B5)-INT(($A5-Q$4*$B5)/$C5)*$C5)*100000+10000-Q$4-INT(($A5-Q$4*$B5)/$C5)) -> 99999999 | ... IY5: =IF(OR($D5<>2,IY$4*$B5+$C5>$A5),99999999,(($A5-IY$4*$B5)-INT(($A5-IY$4*$B5)/$C5)*$C5)*100000+10000-IY$4-INT(($A5-IY$4*$B5)/$C5)) -> 99999999
A6: =CAMBIOS!A6 -> 10 | B6: =IF(D6=1,CAMBIOS!P6*Valor_1+CAMBIOS!Q6*Valor_2+CAMBIOS!R6*Valor_3,IF(CAMBIOS!P6=1,Valor_1,Valor_2)) -> 5 | C6: =IF(D6=1,0,IF(CAMBIOS!R6=1,Valor_3,Valor_2)) -> 0 | D6: =CAMBIOS!P6+CAMBIOS!Q6+CAMBIOS!R6 -> 1 | E6: =MIN(J6:IY6) -> 99999999 | F6: =IF(D6=1,INT(A6/B6),IF(E6>=99999999,0,MATCH(E6,J6:IY6,0))) -> 2 | G6: =IF(D6=1,0,IF(E6>=99999999,0,INT((A6-F6*B6)/C6))) -> 0 | H6: =A6-F6*B6-G6*C6 -> 0 | J6: =IF(OR($D6<>2,J$4*$B6+$C6>$A6),99999999,(($A6-J$4*$B6)-INT(($A6-J$4*$B6)/$C6)*$C6)*100000+10000-J$4-INT(($A6-J$4*$B6)/$C6)) -> 99999999 | K6: =IF(OR($D6<>2,K$4*$B6+$C6>$A6),99999999,(($A6-K$4*$B6)-INT(($A6-K$4*$B6)/$C6)*$C6)*100000+10000-K$4-INT(($A6-K$4*$B6)/$C6)) -> 99999999 | L6: =IF(OR($D6<>2,L$4*$B6+$C6>$A6),99999999,(($A6-L$4*$B6)-INT(($A6-L$4*$B6)/$C6)*$C6)*100000+10000-L$4-INT(($A6-L$4*$B6)/$C6)) -> 99999999 | M6: =IF(OR($D6<>2,M$4*$B6+$C6>$A6),99999999,(($A6-M$4*$B6)-INT(($A6-M$4*$B6)/$C6)*$C6)*100000+10000-M$4-INT(($A6-M$4*$B6)/$C6)) -> 99999999 | N6: =IF(OR($D6<>2,N$4*$B6+$C6>$A6),99999999,(($A6-N$4*$B6)-INT(($A6-N$4*$B6)/$C6)*$C6)*100000+10000-N$4-INT(($A6-N$4*$B6)/$C6)) -> 99999999 | O6: =IF(OR($D6<>2,O$4*$B6+$C6>$A6),99999999,(($A6-O$4*$B6)-INT(($A6-O$4*$B6)/$C6)*$C6)*100000+10000-O$4-INT(($A6-O$4*$B6)/$C6)) -> 99999999 | P6: =IF(OR($D6<>2,P$4*$B6+$C6>$A6),99999999,(($A6-P$4*$B6)-INT(($A6-P$4*$B6)/$C6)*$C6)*100000+10000-P$4-INT(($A6-P$4*$B6)/$C6)) -> 99999999 | Q6: =IF(OR($D6<>2,Q$4*$B6+$C6>$A6),99999999,(($A6-Q$4*$B6)-INT(($A6-Q$4*$B6)/$C6)*$C6)*100000+10000-Q$4-INT(($A6-Q$4*$B6)/$C6)) -> 99999999 | ... IY6: =IF(OR($D6<>2,IY$4*$B6+$C6>$A6),99999999,(($A6-IY$4*$B6)-INT(($A6-IY$4*$B6)/$C6)*$C6)*100000+10000-IY$4-INT(($A6-IY$4*$B6)/$C6)) -> 99999999
A7: =CAMBIOS!A7 -> 10 | B7: =IF(D7=1,CAMBIOS!P7*Valor_1+CAMBIOS!Q7*Valor_2+CAMBIOS!R7*Valor_3,IF(CAMBIOS!P7=1,Valor_1,Valor_2)) -> 7 | C7: =IF(D7=1,0,IF(CAMBIOS!R7=1,Valor_3,Valor_2)) -> 0 | D7: =CAMBIOS!P7+CAMBIOS!Q7+CAMBIOS!R7 -> 1 | E7: =MIN(J7:IY7) -> 99999999 | F7: =IF(D7=1,INT(A7/B7),IF(E7>=99999999,0,MATCH(E7,J7:IY7,0))) -> 1 | G7: =IF(D7=1,0,IF(E7>=99999999,0,INT((A7-F7*B7)/C7))) -> 0 | H7: =A7-F7*B7-G7*C7 -> 3 | J7: =IF(OR($D7<>2,J$4*$B7+$C7>$A7),99999999,(($A7-J$4*$B7)-INT(($A7-J$4*$B7)/$C7)*$C7)*100000+10000-J$4-INT(($A7-J$4*$B7)/$C7)) -> 99999999 | K7: =IF(OR($D7<>2,K$4*$B7+$C7>$A7),99999999,(($A7-K$4*$B7)-INT(($A7-K$4*$B7)/$C7)*$C7)*100000+10000-K$4-INT(($A7-K$4*$B7)/$C7)) -> 99999999 | L7: =IF(OR($D7<>2,L$4*$B7+$C7>$A7),99999999,(($A7-L$4*$B7)-INT(($A7-L$4*$B7)/$C7)*$C7)*100000+10000-L$4-INT(($A7-L$4*$B7)/$C7)) -> 99999999 | M7: =IF(OR($D7<>2,M$4*$B7+$C7>$A7),99999999,(($A7-M$4*$B7)-INT(($A7-M$4*$B7)/$C7)*$C7)*100000+10000-M$4-INT(($A7-M$4*$B7)/$C7)) -> 99999999 | N7: =IF(OR($D7<>2,N$4*$B7+$C7>$A7),99999999,(($A7-N$4*$B7)-INT(($A7-N$4*$B7)/$C7)*$C7)*100000+10000-N$4-INT(($A7-N$4*$B7)/$C7)) -> 99999999 | O7: =IF(OR($D7<>2,O$4*$B7+$C7>$A7),99999999,(($A7-O$4*$B7)-INT(($A7-O$4*$B7)/$C7)*$C7)*100000+10000-O$4-INT(($A7-O$4*$B7)/$C7)) -> 99999999 | P7: =IF(OR($D7<>2,P$4*$B7+$C7>$A7),99999999,(($A7-P$4*$B7)-INT(($A7-P$4*$B7)/$C7)*$C7)*100000+10000-P$4-INT(($A7-P$4*$B7)/$C7)) -> 99999999 | Q7: =IF(OR($D7<>2,Q$4*$B7+$C7>$A7),99999999,(($A7-Q$4*$B7)-INT(($A7-Q$4*$B7)/$C7)*$C7)*100000+10000-Q$4-INT(($A7-Q$4*$B7)/$C7)) -> 99999999 | ... IY7: =IF(OR($D7<>2,IY$4*$B7+$C7>$A7),99999999,(($A7-IY$4*$B7)-INT(($A7-IY$4*$B7)/$C7)*$C7)*100000+10000-IY$4-INT(($A7-IY$4*$B7)/$C7)) -> 99999999
A8: =CAMBIOS!A8 -> 10 | B8: =IF(D8=1,CAMBIOS!P8*Valor_1+CAMBIOS!Q8*Valor_2+CAMBIOS!R8*Valor_3,IF(CAMBIOS!P8=1,Valor_1,Valor_2)) -> 3 | C8: =IF(D8=1,0,IF(CAMBIOS!R8=1,Valor_3,Valor_2)) -> 5 | D8: =CAMBIOS!P8+CAMBIOS!Q8+CAMBIOS!R8 -> 2 | E8: =MIN(J8:IY8) -> 209998 | F8: =IF(D8=1,INT(A8/B8),IF(E8>=99999999,0,MATCH(E8,J8:IY8,0))) -> 1 | G8: =IF(D8=1,0,IF(E8>=99999999,0,INT((A8-F8*B8)/C8))) -> 1 | H8: =A8-F8*B8-G8*C8 -> 2 | J8: =IF(OR($D8<>2,J$4*$B8+$C8>$A8),99999999,(($A8-J$4*$B8)-INT(($A8-J$4*$B8)/$C8)*$C8)*100000+10000-J$4-INT(($A8-J$4*$B8)/$C8)) -> 209998 | K8: =IF(OR($D8<>2,K$4*$B8+$C8>$A8),99999999,(($A8-K$4*$B8)-INT(($A8-K$4*$B8)/$C8)*$C8)*100000+10000-K$4-INT(($A8-K$4*$B8)/$C8)) -> 99999999 | L8: =IF(OR($D8<>2,L$4*$B8+$C8>$A8),99999999,(($A8-L$4*$B8)-INT(($A8-L$4*$B8)/$C8)*$C8)*100000+10000-L$4-INT(($A8-L$4*$B8)/$C8)) -> 99999999 | M8: =IF(OR($D8<>2,M$4*$B8+$C8>$A8),99999999,(($A8-M$4*$B8)-INT(($A8-M$4*$B8)/$C8)*$C8)*100000+10000-M$4-INT(($A8-M$4*$B8)/$C8)) -> 99999999 | N8: =IF(OR($D8<>2,N$4*$B8+$C8>$A8),99999999,(($A8-N$4*$B8)-INT(($A8-N$4*$B8)/$C8)*$C8)*100000+10000-N$4-INT(($A8-N$4*$B8)/$C8)) -> 99999999 | O8: =IF(OR($D8<>2,O$4*$B8+$C8>$A8),99999999,(($A8-O$4*$B8)-INT(($A8-O$4*$B8)/$C8)*$C8)*100000+10000-O$4-INT(($A8-O$4*$B8)/$C8)) -> 99999999 | P8: =IF(OR($D8<>2,P$4*$B8+$C8>$A8),99999999,(($A8-P$4*$B8)-INT(($A8-P$4*$B8)/$C8)*$C8)*100000+10000-P$4-INT(($A8-P$4*$B8)/$C8)) -> 99999999 | Q8: =IF(OR($D8<>2,Q$4*$B8+$C8>$A8),99999999,(($A8-Q$4*$B8)-INT(($A8-Q$4*$B8)/$C8)*$C8)*100000+10000-Q$4-INT(($A8-Q$4*$B8)/$C8)) -> 99999999 | ... IY8: =IF(OR($D8<>2,IY$4*$B8+$C8>$A8),99999999,(($A8-IY$4*$B8)-INT(($A8-IY$4*$B8)/$C8)*$C8)*100000+10000-IY$4-INT(($A8-IY$4*$B8)/$C8)) -> 99999999
A9: =CAMBIOS!A9 -> 10 | B9: =IF(D9=1,CAMBIOS!P9*Valor_1+CAMBIOS!Q9*Valor_2+CAMBIOS!R9*Valor_3,IF(CAMBIOS!P9=1,Valor_1,Valor_2)) -> 3 | C9: =IF(D9=1,0,IF(CAMBIOS!R9=1,Valor_3,Valor_2)) -> 7 | D9: =CAMBIOS!P9+CAMBIOS!Q9+CAMBIOS!R9 -> 2 | E9: =MIN(J9:IY9) -> 9998 | F9: =IF(D9=1,INT(A9/B9),IF(E9>=99999999,0,MATCH(E9,J9:IY9,0))) -> 1 | G9: =IF(D9=1,0,IF(E9>=99999999,0,INT((A9-F9*B9)/C9))) -> 1 | H9: =A9-F9*B9-G9*C9 -> 0 | J9: =IF(OR($D9<>2,J$4*$B9+$C9>$A9),99999999,(($A9-J$4*$B9)-INT(($A9-J$4*$B9)/$C9)*$C9)*100000+10000-J$4-INT(($A9-J$4*$B9)/$C9)) -> 9998 | K9: =IF(OR($D9<>2,K$4*$B9+$C9>$A9),99999999,(($A9-K$4*$B9)-INT(($A9-K$4*$B9)/$C9)*$C9)*100000+10000-K$4-INT(($A9-K$4*$B9)/$C9)) -> 99999999 | L9: =IF(OR($D9<>2,L$4*$B9+$C9>$A9),99999999,(($A9-L$4*$B9)-INT(($A9-L$4*$B9)/$C9)*$C9)*100000+10000-L$4-INT(($A9-L$4*$B9)/$C9)) -> 99999999 | M9: =IF(OR($D9<>2,M$4*$B9+$C9>$A9),99999999,(($A9-M$4*$B9)-INT(($A9-M$4*$B9)/$C9)*$C9)*100000+10000-M$4-INT(($A9-M$4*$B9)/$C9)) -> 99999999 | N9: =IF(OR($D9<>2,N$4*$B9+$C9>$A9),99999999,(($A9-N$4*$B9)-INT(($A9-N$4*$B9)/$C9)*$C9)*100000+10000-N$4-INT(($A9-N$4*$B9)/$C9)) -> 99999999 | O9: =IF(OR($D9<>2,O$4*$B9+$C9>$A9),99999999,(($A9-O$4*$B9)-INT(($A9-O$4*$B9)/$C9)*$C9)*100000+10000-O$4-INT(($A9-O$4*$B9)/$C9)) -> 99999999 | P9: =IF(OR($D9<>2,P$4*$B9+$C9>$A9),99999999,(($A9-P$4*$B9)-INT(($A9-P$4*$B9)/$C9)*$C9)*100000+10000-P$4-INT(($A9-P$4*$B9)/$C9)) -> 99999999 | Q9: =IF(OR($D9<>2,Q$4*$B9+$C9>$A9),99999999,(($A9-Q$4*$B9)-INT(($A9-Q$4*$B9)/$C9)*$C9)*100000+10000-Q$4-INT(($A9-Q$4*$B9)/$C9)) -> 99999999 | ... IY9: =IF(OR($D9<>2,IY$4*$B9+$C9>$A9),99999999,(($A9-IY$4*$B9)-INT(($A9-IY$4*$B9)/$C9)*$C9)*100000+10000-IY$4-INT(($A9-IY$4*$B9)/$C9)) -> 99999999
A10: =CAMBIOS!A10 -> 10 | B10: =IF(D10=1,CAMBIOS!P10*Valor_1+CAMBIOS!Q10*Valor_2+CAMBIOS!R10*Valor_3,IF(CAMBIOS!P10=1,Valor_1,Valor_2)) -> 5 | C10: =IF(D10=1,0,IF(CAMBIOS!R10=1,Valor_3,Valor_2)) -> 7 | D10: =CAMBIOS!P10+CAMBIOS!Q10+CAMBIOS!R10 -> 2 | E10: =MIN(J10:IY10) -> 99999999 | F10: =IF(D10=1,INT(A10/B10),IF(E10>=99999999,0,MATCH(E10,J10:IY10,0))) -> 0 | G10: =IF(D10=1,0,IF(E10>=99999999,0,INT((A10-F10*B10)/C10))) -> 0 | H10: =A10-F10*B10-G10*C10 -> 10 | J10: =IF(OR($D10<>2,J$4*$B10+$C10>$A10),99999999,(($A10-J$4*$B10)-INT(($A10-J$4*$B10)/$C10)*$C10)*100000+10000-J$4-INT(($A10-J$4*$B10)/$C10)) -> 99999999 | K10: =IF(OR($D10<>2,K$4*$B10+$C10>$A10),99999999,(($A10-K$4*$B10)-INT(($A10-K$4*$B10)/$C10)*$C10)*100000+10000-K$4-INT(($A10-K$4*$B10)/$C10)) -> 99999999 | L10: =IF(OR($D10<>2,L$4*$B10+$C10>$A10),99999999,(($A10-L$4*$B10)-INT(($A10-L$4*$B10)/$C10)*$C10)*100000+10000-L$4-INT(($A10-L$4*$B10)/$C10)) -> 99999999 | M10: =IF(OR($D10<>2,M$4*$B10+$C10>$A10),99999999,(($A10-M$4*$B10)-INT(($A10-M$4*$B10)/$C10)*$C10)*100000+10000-M$4-INT(($A10-M$4*$B10)/$C10)) -> 99999999 | N10: =IF(OR($D10<>2,N$4*$B10+$C10>$A10),99999999,(($A10-N$4*$B10)-INT(($A10-N$4*$B10)/$C10)*$C10)*100000+10000-N$4-INT(($A10-N$4*$B10)/$C10)) -> 99999999 | O10: =IF(OR($D10<>2,O$4*$B10+$C10>$A10),99999999,(($A10-O$4*$B10)-INT(($A10-O$4*$B10)/$C10)*$C10)*100000+10000-O$4-INT(($A10-O$4*$B10)/$C10)) -> 99999999 | P10: =IF(OR($D10<>2,P$4*$B10+$C10>$A10),99999999,(($A10-P$4*$B10)-INT(($A10-P$4*$B10)/$C10)*$C10)*100000+10000-P$4-INT(($A10-P$4*$B10)/$C10)) -> 99999999 | Q10: =IF(OR($D10<>2,Q$4*$B10+$C10>$A10),99999999,(($A10-Q$4*$B10)-INT(($A10-Q$4*$B10)/$C10)*$C10)*100000+10000-Q$4-INT(($A10-Q$4*$B10)/$C10)) -> 99999999 | ... IY10: =IF(OR($D10<>2,IY$4*$B10+$C10>$A10),99999999,(($A10-IY$4*$B10)-INT(($A10-IY$4*$B10)/$C10)*$C10)*100000+10000-IY$4-INT(($A10-IY$4*$B10)/$C10)) -> 99999999
